Workbook

Sheet РЕЙД-КОНСТРУКТОР
A1: CoA RAID COMP — КОНСТРУКТОР СОСТАВА | O1: НАСТРОЙКИ И РЕЙДОВЫЙ СОВЕТНИК
A2: Заполняй класс и специализацию. Роль определяется автоматически. Сначала закрываются критические эффекты и роли; затем решают логи, выживаемость и уникальность состава. | O2: Профиль | P2: Безопасность | Q2: Уникальность | R2: Умеренно | S2: Макс. спек | T2: 5 | U2: Макс. класс | V2: 3
A3: Роль для рекомендаций | C3: Любая | D3: Игроков | E3: =SUM(H6:H30) -> 0 | F3: Крит. не хватает | G3: =COUNTIFS('СПРАВОЧНИК ЭФФЕКТОВ'!$D$4:$D$48,0,'СПРАВОЧНИК ЭФФЕКТОВ'!$C$4:$C$48,"Критично") -> 20 | H3: =IFERROR(SUMPRODUCT(--('СПРАВОЧНИК ЭФФЕКТОВ'!$D$4:$D$48>0),IF('СПРАВОЧНИК ЭФФЕКТОВ'!$C$4:$C$48="Критично",3,IF('СПРАВОЧНИК ЭФФЕКТОВ'!$C$4:$C$48="Важно",2,IF('СПРАВОЧНИК ЭФФЕКТОВ'!$C$4:$C$48="Опционально",1,0))))/SUM(IF('СПРАВОЧНИК ЭФФЕКТОВ'!$C$4:$C$48="Критично",3,IF('СПРАВОЧНИК ЭФФЕКТОВ'!$C$4:$C$48="Важно",2,IF('СПРАВОЧНИК ЭФФЕКТОВ'!$C$4:$C$48="Опционально",1,0)))),0) -> 0 | I3: =COUNTIF(K6:K50,0) -> 45 | J3: Критично | K3: =COUNTIFS(K6:K50,0,M6:M50,"Критично") -> 20 | L3: Готовность | M3: =IFERROR(SUMPRODUCT(--(K6:K50>0),N6:N50)/SUM(N6:N50),0) -> 0 | O3: Профиль состава | P3: Универсальный | Q3: Цель игроков | R3: 25 | S3: Осталось | T3: =MAX($R$3-$E$3,0) -> 25 | U3: Лимиты | V3: =$T$2&" одинаковых спека / "&$V$2&" игроков класса" -> 5 одинаковых спека / 3 игроков класса
A4: СОСТАВ РЕЙДА — 25 СЛОТОВ | I4: ПОКРЫТИЕ РЕЙДА — ЧЕГО НЕ ХВАТАЕТ
A5: Слот | B5: Игрок | C5: Класс | D5: Специализация | E5: Роль | F5: Кол-во* | G5: Проверка | H5: Учтено | I5: Категория | J5: Эффект | K5: В рейде | L5: Статус | M5: Приоритет | N5: Вес | O5: СЛЕДУЮЩИЙ ЛУЧШИЙ ВЫБОР — ДОБАВИТЬ СЕЙЧАС
A6: 1 | B6: Gunspojoshe | F6: 1 | G6: =IF(AND(C6="",D6=""),"",IF(OR(C6="",D6=""),"ЗАПОЛНИ ПАРУ",IF(COUNTIFS(ТЕХ_Списки!$A$2:$A$71,C6,ТЕХ_Списки!$B$2:$B$71,D6)<>1,"НЕВЕРНАЯ ПАРА",IF(E6="","РОЛЬ НЕ НАЙДЕНА",IF(AND($R$2<>"Без ограничений",OR(SUMIF(ТЕХ_Расчет!$A$2:$A$26,C6&"§"&D6,ТЕХ_Расчет!$B$2:$B$26)>$T$2,SUMIF($C$6:$C$30,C6,$H$6:$H$30)>$V$2)),"ПРЕВЫШЕН ЛИМИТ","OK"))))) | H6: =IF(OR(C6="",D6=""),0,IF(F6="",1,F6)) -> 0 | I6: Физические бафы | J6: 10% Stats | K6: =ТЕХ_Расчет!D$43 -> 0 | L6: =IF(K6=0,"НЕ ХВАТАЕТ",IF(K6=1,"ЕСТЬ","ЕСТЬ ЗАПАС")) -> НЕ ХВАТАЕТ | M6: ='СПРАВОЧНИК ЭФФЕКТОВ'!C4 -> Критично | N6: =IF(M6="Критично",3,IF(M6="Важно",2,IF(M6="Опционально",1,0))) -> 3 | O6: =IF($E$3>=$R$3,"СОСТАВ ЗАПОЛНЕН",IFERROR(INDEX(ТЕХ_Подсказки!$A$2:$V$71,$N$54,1)&" — "&INDEX(ТЕХ_Подсказки!$A$2:$V$71,$N$54,2)&" ("&INDEX(ТЕХ_Подсказки!$A$2:$V$71,$N$54,3)&")","НЕТ ДОСТУПНОЙ РЕКОМЕНДАЦИИ")) -> Felsworn — Tyrant (Танк)
A7: 2 | F7: 1 | G7: =IF(AND(C7="",D7=""),"",IF(OR(C7="",D7=""),"ЗАПОЛНИ ПАРУ",IF(COUNTIFS(ТЕХ_Списки!$A$2:$A$71,C7,ТЕХ_Списки!$B$2:$B$71,D7)<>1,"НЕВЕРНАЯ ПАРА",IF(E7="","РОЛЬ НЕ НАЙДЕНА",IF(AND($R$2<>"Без ограничений",OR(SUMIF(ТЕХ_Расчет!$A$2:$A$26,C7&"§"&D7,ТЕХ_Расчет!$B$2:$B$26)>$T$2,SUMIF($C$6:$C$30,C7,$H$6:$H$30)>$V$2)),"ПРЕВЫШЕН ЛИМИТ","OK"))))) | H7: =IF(OR(C7="",D7=""),0,IF(F7="",1,F7)) -> 0 | I7: Физические бафы | J7: Minor Armor and All Stats | K7: =ТЕХ_Расчет!E$43 -> 0 | L7: =IF(K7=0,"НЕ ХВАТАЕТ",IF(K7=1,"ЕСТЬ","ЕСТЬ ЗАПАС")) -> НЕ ХВАТАЕТ | M7: ='СПРАВОЧНИК ЭФФЕКТОВ'!C5 -> Важно | N7: =IF(M7="Критично",3,IF(M7="Важно",2,IF(M7="Опционально",1,0))) -> 2 | O7: Крит. | P7: =IFERROR(INDEX(ТЕХ_Подсказки!$A$2:$V$71,$N$54,13),"") -> 0 | Q7: Важн. | R7: =IFERROR(INDEX(ТЕХ_Подсказки!$A$2:$V$71,$N$54,14),"") -> 0 | S7: Логи | T7: =IFERROR(INDEX(ТЕХ_Подсказки!$A$2:$V$71,$N$54,9),"") -> 88.24 | U7: =IFERROR(INDEX(ТЕХ_Подсказки!$A$2:$V$71,$N$54,19),"") -> 158.24 | V7: =IFERROR(INDEX(ТЕХ_Подсказки!$A$2:$V$71,$N$54,3),"") -> Танк
A8: 3 | F8: 1 | G8: =IF(AND(C8="",D8=""),"",IF(OR(C8="",D8=""),"ЗАПОЛНИ ПАРУ",IF(COUNTIFS(ТЕХ_Списки!$A$2:$A$71,C8,ТЕХ_Списки!$B$2:$B$71,D8)<>1,"НЕВЕРНАЯ ПАРА",IF(E8="","РОЛЬ НЕ НАЙДЕНА",IF(AND($R$2<>"Без ограничений",OR(SUMIF(ТЕХ_Расчет!$A$2:$A$26,C8&"§"&D8,ТЕХ_Расчет!$B$2:$B$26)>$T$2,SUMIF($C$6:$C$30,C8,$H$6:$H$30)>$V$2)),"ПРЕВЫШЕН ЛИМИТ","OK"))))) | H8: =IF(OR(C8="",D8=""),0,IF(F8="",1,F8)) -> 0 | I8: Физические бафы | J8: Stamina | K8: =ТЕХ_Расчет!F$43 -> 0 | L8: =IF(K8=0,"НЕ ХВАТАЕТ",IF(K8=1,"ЕСТЬ","ЕСТЬ ЗАПАС")) -> НЕ ХВАТАЕТ | M8: ='СПРАВОЧНИК ЭФФЕКТОВ'!C6 -> Важно | N8: =IF(M8="Критично",3,IF(M8="Важно",2,IF(M8="Опционально",1,0))) -> 2 | O8: =IF($E$3>=$R$3,"Все 25 слотов заполнены.",IFERROR(INDEX(ТЕХ_Подсказки!$A$2:$V$71,$N$54,22),"Рекомендация не рассчитана.")) -> Критичные и важные эффекты закрыты — выбор по роли и логам: DTPS 215, 88/100.
A9: 4 | F9: 1 | G9: =IF(AND(C9="",D9=""),"",IF(OR(C9="",D9=""),"ЗАПОЛНИ ПАРУ",IF(COUNTIFS(ТЕХ_Списки!$A$2:$A$71,C9,ТЕХ_Списки!$B$2:$B$71,D9)<>1,"НЕВЕРНАЯ ПАРА",IF(E9="","РОЛЬ НЕ НАЙДЕНА",IF(AND($R$2<>"Без ограничений",OR(SUMIF(ТЕХ_Расчет!$A$2:$A$26,C9&"§"&D9,ТЕХ_Расчет!$B$2:$B$26)>$T$2,SUMIF($C$6:$C$30,C9,$H$6:$H$30)>$V$2)),"ПРЕВЫШЕН ЛИМИТ","OK"))))) | H9: =IF(OR(C9="",D9=""),0,IF(F9="",1,F9)) -> 0 | I9: Физические бафы | J9: Strength | K9: =ТЕХ_Расчет!G$43 -> 0 | L9: =IF(K9=0,"НЕ ХВАТАЕТ",IF(K9=1,"ЕСТЬ","ЕСТЬ ЗАПАС")) -> НЕ ХВАТАЕТ | M9: ='СПРАВОЧНИК ЭФФЕКТОВ'!C7 -> Важно | N9: =IF(M9="Критично",3,IF(M9="Важно",2,IF(M9="Опционально",1,0))) -> 2
A10: 5 | F10: 1 | G10: =IF(AND(C10="",D10=""),"",IF(OR(C10="",D10=""),"ЗАПОЛНИ ПАРУ",IF(COUNTIFS(ТЕХ_Списки!$A$2:$A$71,C10,ТЕХ_Списки!$B$2:$B$71,D10)<>1,"НЕВЕРНАЯ ПАРА",IF(E10="","РОЛЬ НЕ НАЙДЕНА",IF(AND($R$2<>"Без ограничений",OR(SUMIF(ТЕХ_Расчет!$A$2:$A$26,C10&"§"&D10,ТЕХ_Расчет!$B$2:$B$26)>$T$2,SUMIF($C$6:$C$30,C10,$H$6:$H$30)>$V$2)),"ПРЕВЫШЕН ЛИМИТ","OK"))))) | H10: =IF(OR(C10="",D10=""),0,IF(F10="",1,F10)) -> 0 | I10: Физические бафы | J10: Agility | K10: =ТЕХ_Расчет!H$43 -> 0 | L10: =IF(K10=0,"НЕ ХВАТАЕТ",IF(K10=1,"ЕСТЬ","ЕСТЬ ЗАПАС")) -> НЕ ХВАТАЕТ | M10: ='СПРАВОЧНИК ЭФФЕКТОВ'!C8 -> Важно | N10: =IF(M10="Критично",3,IF(M10="Важно",2,IF(M10="Опционально",1,0))) -> 2
A11: 6 | F11: 1 | G11: =IF(AND(C11="",D11=""),"",IF(OR(C11="",D11=""),"ЗАПОЛНИ ПАРУ",IF(COUNTIFS(ТЕХ_Списки!$A$2:$A$71,C11,ТЕХ_Списки!$B$2:$B$71,D11)<>1,"НЕВЕРНАЯ ПАРА",IF(E11="","РОЛЬ НЕ НАЙДЕНА",IF(AND($R$2<>"Без ограничений",OR(SUMIF(ТЕХ_Расчет!$A$2:$A$26,C11&"§"&D11,ТЕХ_Расчет!$B$2:$B$26)>$T$2,SUMIF($C$6:$C$30,C11,$H$6:$H$30)>$V$2)),"ПРЕВЫШЕН ЛИМИТ","OK"))))) | H11: =IF(OR(C11="",D11=""),0,IF(F11="",1,F11)) -> 0 | I11: Физические бафы | J11: Attack Power | K11: =ТЕХ_Расчет!I$43 -> 0 | L11: =IF(K11=0,"НЕ ХВАТАЕТ",IF(K11=1,"ЕСТЬ","ЕСТЬ ЗАПАС")) -> НЕ ХВАТАЕТ | M11: ='СПРАВОЧНИК ЭФФЕКТОВ'!C9 -> Важно | N11: =IF(M11="Критично",3,IF(M11="Важно",2,IF(M11="Опционально",1,0))) -> 2 | O11: =IF(COUNT(ТЕХ_Подсказки!$T$2:$T$71)>0,"Расчёт активен. Профиль: "&P2&"; уникальность: "&R2&"; лимиты: "&T2&" спека / "&V2&" класса.","Нет рассчитанных вариантов. В Excel включите автоматический пересчёт формул.") -> Расчёт активен. Профиль: Безопасность; уникальность: Умеренно; лимиты: 5 спека / 3 класса.
A12: 7 | F12: 1 | G12: =IF(AND(C12="",D12=""),"",IF(OR(C12="",D12=""),"ЗАПОЛНИ ПАРУ",IF(COUNTIFS(ТЕХ_Списки!$A$2:$A$71,C12,ТЕХ_Списки!$B$2:$B$71,D12)<>1,"НЕВЕРНАЯ ПАРА",IF(E12="","РОЛЬ НЕ НАЙДЕНА",IF(AND($R$2<>"Без ограничений",OR(SUMIF(ТЕХ_Расчет!$A$2:$A$26,C12&"§"&D12,ТЕХ_Расчет!$B$2:$B$26)>$T$2,SUMIF($C$6:$C$30,C12,$H$6:$H$30)>$V$2)),"ПРЕВЫШЕН ЛИМИТ","OK"))))) | H12: =IF(OR(C12="",D12=""),0,IF(F12="",1,F12)) -> 0 | I12: Физические бафы | J12: 5% Attack Power | K12: =ТЕХ_Расчет!J$43 -> 0 | L12: =IF(K12=0,"НЕ ХВАТАЕТ",IF(K12=1,"ЕСТЬ","ЕСТЬ ЗАПАС")) -> НЕ ХВАТАЕТ | M12: ='СПРАВОЧНИК ЭФФЕКТОВ'!C10 -> Критично | N12: =IF(M12="Критично",3,IF(M12="Важно",2,IF(M12="Опционально",1,0))) -> 3
A13: 8 | F13: 1 | G13: =IF(AND(C13="",D13=""),"",IF(OR(C13="",D13=""),"ЗАПОЛНИ ПАРУ",IF(COUNTIFS(ТЕХ_Списки!$A$2:$A$71,C13,ТЕХ_Списки!$B$2:$B$71,D13)<>1,"НЕВЕРНАЯ ПАРА",IF(E13="","РОЛЬ НЕ НАЙДЕНА",IF(AND($R$2<>"Без ограничений",OR(SUMIF(ТЕХ_Расчет!$A$2:$A$26,C13&"§"&D13,ТЕХ_Расчет!$B$2:$B$26)>$T$2,SUMIF($C$6:$C$30,C13,$H$6:$H$30)>$V$2)),"ПРЕВЫШЕН ЛИМИТ","OK"))))) | H13: =IF(OR(C13="",D13=""),0,IF(F13="",1,F13)) -> 0 | I13: Физические бафы | J13: 10% Melee & Range Haste | K13: =ТЕХ_Расчет!K$43 -> 0 | L13: =IF(K13=0,"НЕ ХВАТАЕТ",IF(K13=1,"ЕСТЬ","ЕСТЬ ЗАПАС")) -> НЕ ХВАТАЕТ | M13: ='СПРАВОЧНИК ЭФФЕКТОВ'!C11 -> Критично | N13: =IF(M13="Критично",3,IF(M13="Важно",2,IF(M13="Опционально",1,0))) -> 3 | O13: НЕДОСТАЮЩИЕ ЭФФЕКТЫ — ПРИОРИТЕТ И ИСТОЧНИКИ
A14: 9 | F14: 1 | G14: =IF(AND(C14="",D14=""),"",IF(OR(C14="",D14=""),"ЗАПОЛНИ ПАРУ",IF(COUNTIFS(ТЕХ_Списки!$A$2:$A$71,C14,ТЕХ_Списки!$B$2:$B$71,D14)<>1,"НЕВЕРНАЯ ПАРА",IF(E14="","РОЛЬ НЕ НАЙДЕНА",IF(AND($R$2<>"Без ограничений",OR(SUMIF(ТЕХ_Расчет!$A$2:$A$26,C14&"§"&D14,ТЕХ_Расчет!$B$2:$B$26)>$T$2,SUMIF($C$6:$C$30,C14,$H$6:$H$30)>$V$2)),"ПРЕВЫШЕН ЛИМИТ","OK"))))) | H14: =IF(OR(C14="",D14=""),0,IF(F14="",1,F14)) -> 0 | I14: Кастерские бафы | J14: Intellect | K14: =ТЕХ_Расчет!L$43 -> 0 | L14: =IF(K14=0,"НЕ ХВАТАЕТ",IF(K14=1,"ЕСТЬ","ЕСТЬ ЗАПАС")) -> НЕ ХВАТАЕТ | M14: ='СПРАВОЧНИК ЭФФЕКТОВ'!C12 -> Важно | N14: =IF(M14="Критично",3,IF(M14="Важно",2,IF(M14="Опционально",1,0))) -> 2 | O14: Приор. | P14: Эффект | S14: Кто даёт
A15: 10 | G15: =IF(AND(C15="",D15=""),"",IF(OR(C15="",D15=""),"ЗАПОЛНИ ПАРУ",IF(COUNTIFS(ТЕХ_Списки!$A$2:$A$71,C15,ТЕХ_Списки!$B$2:$B$71,D15)<>1,"НЕВЕРНАЯ ПАРА",IF(E15="","РОЛЬ НЕ НАЙДЕНА",IF(AND($R$2<>"Без ограничений",OR(SUMIF(ТЕХ_Расчет!$A$2:$A$26,C15&"§"&D15,ТЕХ_Расчет!$B$2:$B$26)>$T$2,SUMIF($C$6:$C$30,C15,$H$6:$H$30)>$V$2)),"ПРЕВЫШЕН ЛИМИТ","OK"))))) | H15: =IF(OR(C15="",D15=""),0,IF(F15="",1,F15)) -> 0 | I15: Кастерские бафы | J15: Spirit | K15: =ТЕХ_Расчет!M$43 -> 0 | L15: =IF(K15=0,"НЕ ХВАТАЕТ",IF(K15=1,"ЕСТЬ","ЕСТЬ ЗАПАС")) -> НЕ ХВАТАЕТ | M15: ='СПРАВОЧНИК ЭФФЕКТОВ'!C13 -> Важно | N15: =IF(M15="Критично",3,IF(M15="Важно",2,IF(M15="Опционально",1,0))) -> 2 | O15: =IFERROR(INDEX(ТЕХ_Подсказки!$BU$2:$BU$46,MATCH(LARGE(ТЕХ_Подсказки!$BX$2:$BX$46,1),ТЕХ_Подсказки!$BX$2:$BX$46,0)),"") -> Критично | P15: =IFERROR(INDEX(ТЕХ_Подсказки!$BT$2:$BT$46,MATCH(LARGE(ТЕХ_Подсказки!$BX$2:$BX$46,1),ТЕХ_Подсказки!$BX$2:$BX$46,0)),"") -> Defensive Cooldown (Raid-Wide) | S15: =IFERROR(INDEX(ТЕХ_Подсказки!$BW$2:$BW$46,MATCH(LARGE(ТЕХ_Подсказки!$BX$2:$BX$46,1),ТЕХ_Подсказки!$BX$2:$BX$46,0)),"") -> Felsworn — Tyrant; Sun Cleric — Seraphim; Templar — Oathkeeper; Witch Hunter — Black Knight
A16: 11 | E16: =IF(OR(C16="",D16=""),"",IFERROR(INDEX(ТЕХ_Списки!$C$2:$C$71,MATCH(C16&"§"&D16,ТЕХ_Списки!$D$2:$D$71,0)),"")) | G16: =IF(AND(C16="",D16=""),"",IF(OR(C16="",D16=""),"ЗАПОЛНИ ПАРУ",IF(COUNTIFS(ТЕХ_Списки!$A$2:$A$71,C16,ТЕХ_Списки!$B$2:$B$71,D16)<>1,"НЕВЕРНАЯ ПАРА",IF(E16="","РОЛЬ НЕ НАЙДЕНА",IF(AND($R$2<>"Без ограничений",OR(SUMIF(ТЕХ_Расчет!$A$2:$A$26,C16&"§"&D16,ТЕХ_Расчет!$B$2:$B$26)>$T$2,SUMIF($C$6:$C$30,C16,$H$6:$H$30)>$V$2)),"ПРЕВЫШЕН ЛИМИТ","OK"))))) | H16: =IF(OR(C16="",D16=""),0,IF(F16="",1,F16)) -> 0 | I16: Кастерские бафы | J16: Spell Power | K16: =ТЕХ_Расчет!N$43 -> 0 | L16: =IF(K16=0,"НЕ ХВАТАЕТ",IF(K16=1,"ЕСТЬ","ЕСТЬ ЗАПАС")) -> НЕ ХВАТАЕТ | M16: ='СПРАВОЧНИК ЭФФЕКТОВ'!C14 -> Важно | N16: =IF(M16="Критично",3,IF(M16="Важно",2,IF(M16="Опционально",1,0))) -> 2 | O16: =IFERROR(INDEX(ТЕХ_Подсказки!$BU$2:$BU$46,MATCH(LARGE(ТЕХ_Подсказки!$BX$2:$BX$46,2),ТЕХ_Подсказки!$BX$2:$BX$46,0)),"") -> Критично | P16: =IFERROR(INDEX(ТЕХ_Подсказки!$BT$2:$BT$46,MATCH(LARGE(ТЕХ_Подсказки!$BX$2:$BX$46,2),ТЕХ_Подсказки!$BX$2:$BX$46,0)),"") -> Heroism | Bloodlust | S16: =IFERROR(INDEX(ТЕХ_Подсказки!$BW$2:$BW$46,MATCH(LARGE(ТЕХ_Подсказки!$BX$2:$BX$46,2),ТЕХ_Подсказки!$BX$2:$BX$46,0)),"") -> Barbarian — Ancestry; Bloodmage — Fleshweaver; Guardian — Inspiration; Primalist — Grovekeeper; + ещё 2 классов
A17: 12 | E17: =IF(OR(C17="",D17=""),"",IFERROR(INDEX(ТЕХ_Списки!$C$2:$C$71,MATCH(C17&"§"&D17,ТЕХ_Списки!$D$2:$D$71,0)),"")) | G17: =IF(AND(C17="",D17=""),"",IF(OR(C17="",D17=""),"ЗАПОЛНИ ПАРУ",IF(COUNTIFS(ТЕХ_Списки!$A$2:$A$71,C17,ТЕХ_Списки!$B$2:$B$71,D17)<>1,"НЕВЕРНАЯ ПАРА",IF(E17="","РОЛЬ НЕ НАЙДЕНА",IF(AND($R$2<>"Без ограничений",OR(SUMIF(ТЕХ_Расчет!$A$2:$A$26,C17&"§"&D17,ТЕХ_Расчет!$B$2:$B$26)>$T$2,SUMIF($C$6:$C$30,C17,$H$6:$H$30)>$V$2)),"ПРЕВЫШЕН ЛИМИТ","OK"))))) | H17: =IF(OR(C17="",D17=""),0,IF(F17="",1,F17)) -> 0 | I17: Кастерские бафы | J17: 3% Spell Haste | K17: =ТЕХ_Расчет!O$43 -> 0 | L17: =IF(K17=0,"НЕ ХВАТАЕТ",IF(K17=1,"ЕСТЬ","ЕСТЬ ЗАПАС")) -> НЕ ХВАТАЕТ | M17: ='СПРАВОЧНИК ЭФФЕКТОВ'!C15 -> Критично | N17: =IF(M17="Критично",3,IF(M17="Важно",2,IF(M17="Опционально",1,0))) -> 3 | O17: =IFERROR(INDEX(ТЕХ_Подсказки!$BU$2:$BU$46,MATCH(LARGE(ТЕХ_Подсказки!$BX$2:$BX$46,3),ТЕХ_Подсказки!$BX$2:$BX$46,0)),"") -> Критично | P17: =IFERROR(INDEX(ТЕХ_Подсказки!$BT$2:$BT$46,MATCH(LARGE(ТЕХ_Подсказки!$BX$2:$BX$46,3),ТЕХ_Подсказки!$BX$2:$BX$46,0)),"") -> Armor | S17: =IFERROR(INDEX(ТЕХ_Подсказки!$BW$2:$BW$46,MATCH(LARGE(ТЕХ_Подсказки!$BX$2:$BX$46,3),ТЕХ_Подсказки!$BX$2:$BX$46,0)),"") -> Barbarian — Ancestry; Bloodmage — Fleshweaver; Felsworn — Slaying; Guardian — Inspiration; + ещё 3 классов
A18: 13 | E18: =IF(OR(C18="",D18=""),"",IFERROR(INDEX(ТЕХ_Списки!$C$2:$C$71,MATCH(C18&"§"&D18,ТЕХ_Списки!$D$2:$D$71,0)),"")) | G18: =IF(AND(C18="",D18=""),"",IF(OR(C18="",D18=""),"ЗАПОЛНИ ПАРУ",IF(COUNTIFS(ТЕХ_Списки!$A$2:$A$71,C18,ТЕХ_Списки!$B$2:$B$71,D18)<>1,"НЕВЕРНАЯ ПАРА",IF(E18="","РОЛЬ НЕ НАЙДЕНА",IF(AND($R$2<>"Без ограничений",OR(SUMIF(ТЕХ_Расчет!$A$2:$A$26,C18&"§"&D18,ТЕХ_Расчет!$B$2:$B$26)>$T$2,SUMIF($C$6:$C$30,C18,$H$6:$H$30)>$V$2)),"ПРЕВЫШЕН ЛИМИТ","OK"))))) | H18: =IF(OR(C18="",D18=""),0,IF(F18="",1,F18)) -> 0 | I18: Кастерские бафы | J18: Mana Regeneration | K18: =ТЕХ_Расчет!P$43 -> 0 | L18: =IF(K18=0,"НЕ ХВАТАЕТ",IF(K18=1,"ЕСТЬ","ЕСТЬ ЗАПАС")) -> НЕ ХВАТАЕТ | M18: ='СПРАВОЧНИК ЭФФЕКТОВ'!C16 -> Важно | N18: =IF(M18="Критично",3,IF(M18="Важно",2,IF(M18="Опционально",1,0))) -> 2 | O18: =IFERROR(INDEX(ТЕХ_Подсказки!$BU$2:$BU$46,MATCH(LARGE(ТЕХ_Подсказки!$BX$2:$BX$46,4),ТЕХ_Подсказки!$BX$2:$BX$46,0)),"") -> Критично | P18: =IFERROR(INDEX(ТЕХ_Подсказки!$BT$2:$BT$46,MATCH(LARGE(ТЕХ_Подсказки!$BX$2:$BX$46,4),ТЕХ_Подсказки!$BX$2:$BX$46,0)),"") -> 3% Spell Hit | S18: =IFERROR(INDEX(ТЕХ_Подсказки!$BW$2:$BW$46,MATCH(LARGE(ТЕХ_Подсказки!$BX$2:$BX$46,4),ТЕХ_Подсказки!$BX$2:$BX$46,0)),"") -> Chronomancer — Infinite; Cultist — Corruption; Felsworn — Infernal; Primalist — Geomancy; + ещё 3 классов
A19: 14 | E19: =IF(OR(C19="",D19=""),"",IFERROR(INDEX(ТЕХ_Списки!$C$2:$C$71,MATCH(C19&"§"&D19,ТЕХ_Списки!$D$2:$D$71,0)),"")) | G19: =IF(AND(C19="",D19=""),"",IF(OR(C19="",D19=""),"ЗАПОЛНИ ПАРУ",IF(COUNTIFS(ТЕХ_Списки!$A$2:$A$71,C19,ТЕХ_Списки!$B$2:$B$71,D19)<>1,"НЕВЕРНАЯ ПАРА",IF(E19="","РОЛЬ НЕ НАЙДЕНА",IF(AND($R$2<>"Без ограничений",OR(SUMIF(ТЕХ_Расчет!$A$2:$A$26,C19&"§"&D19,ТЕХ_Расчет!$B$2:$B$26)>$T$2,SUMIF($C$6:$C$30,C19,$H$6:$H$30)>$V$2)),"ПРЕВЫШЕН ЛИМИТ","OK"))))) | H19: =IF(OR(C19="",D19=""),0,IF(F19="",1,F19)) -> 0 | I19: Кастерские бафы | J19: Replenishment | K19: =ТЕХ_Расчет!Q$43 -> 0 | L19: =IF(K19=0,"НЕ ХВАТАЕТ",IF(K19=1,"ЕСТЬ","ЕСТЬ ЗАПАС")) -> НЕ ХВАТАЕТ | M19: ='СПРАВОЧНИК ЭФФЕКТОВ'!C17 -> Критично | N19: =IF(M19="Критично",3,IF(M19="Важно",2,IF(M19="Опционально",1,0))) -> 3 | O19: =IFERROR(INDEX(ТЕХ_Подсказки!$BU$2:$BU$46,MATCH(LARGE(ТЕХ_Подсказки!$BX$2:$BX$46,5),ТЕХ_Подсказки!$BX$2:$BX$46,0)),"") -> Критично | P19: =IFERROR(INDEX(ТЕХ_Подсказки!$BT$2:$BT$46,MATCH(LARGE(ТЕХ_Подсказки!$BX$2:$BX$46,5),ТЕХ_Подсказки!$BX$2:$BX$46,0)),"") -> 4% Physical Damage | S19: =IFERROR(INDEX(ТЕХ_Подсказки!$BW$2:$BW$46,MATCH(LARGE(ТЕХ_Подсказки!$BX$2:$BX$46,5),ТЕХ_Подсказки!$BX$2:$BX$46,0)),"") -> Barbarian — Brutality; Felsworn — Tyrant; Guardian — Gladiator; Knight of Xoroth — War; + ещё 3 классов
A20: 15 | E20: =IF(OR(C20="",D20=""),"",IFERROR(INDEX(ТЕХ_Списки!$C$2:$C$71,MATCH(C20&"§"&D20,ТЕХ_Списки!$D$2:$D$71,0)),"")) | G20: =IF(AND(C20="",D20=""),"",IF(OR(C20="",D20=""),"ЗАПОЛНИ ПАРУ",IF(COUNTIFS(ТЕХ_Списки!$A$2:$A$71,C20,ТЕХ_Списки!$B$2:$B$71,D20)<>1,"НЕВЕРНАЯ ПАРА",IF(E20="","РОЛЬ НЕ НАЙДЕНА",IF(AND($R$2<>"Без ограничений",OR(SUMIF(ТЕХ_Расчет!$A$2:$A$26,C20&"§"&D20,ТЕХ_Расчет!$B$2:$B$26)>$T$2,SUMIF($C$6:$C$30,C20,$H$6:$H$30)>$V$2)),"ПРЕВЫШЕН ЛИМИТ","OK"))))) | H20: =IF(OR(C20="",D20=""),0,IF(F20="",1,F20)) -> 0 | I20: Кастерские бафы | J20: Strong Mana Cooldown | K20: =ТЕХ_Расчет!R$43 -> 0 | L20: =IF(K20=0,"НЕ ХВАТАЕТ",IF(K20=1,"ЕСТЬ","ЕСТЬ ЗАПАС")) -> НЕ ХВАТАЕТ | M20: ='СПРАВОЧНИК ЭФФЕКТОВ'!C18 -> Опционально | N20: =IF(M20="Критично",3,IF(M20="Важно",2,IF(M20="Опционально",1,0))) -> 1 | O20: =IFERROR(INDEX(ТЕХ_Подсказки!$BU$2:$BU$46,MATCH(LARGE(ТЕХ_Подсказки!$BX$2:$BX$46,6),ТЕХ_Подсказки!$BX$2:$BX$46,0)),"") -> Критично | P20: =IFERROR(INDEX(ТЕХ_Подсказки!$BT$2:$BT$46,MATCH(LARGE(ТЕХ_Подсказки!$BX$2:$BX$46,6),ТЕХ_Подсказки!$BX$2:$BX$46,0)),"") -> 3% Damage Done (all) | S20: =IFERROR(INDEX(ТЕХ_Подсказки!$BW$2:$BW$46,MATCH(LARGE(ТЕХ_Подсказки!$BX$2:$BX$46,6),ТЕХ_Подсказки!$BX$2:$BX$46,0)),"") -> Chronomancer — Infinite; Felsworn — Tyrant; Knight of Xoroth — Hellfire; Necromancer — Animation; + ещё 5 классов
A21: 16 | E21: =IF(OR(C21="",D21=""),"",IFERROR(INDEX(ТЕХ_Списки!$C$2:$C$71,MATCH(C21&"§"&D21,ТЕХ_Списки!$D$2:$D$71,0)),"")) | G21: =IF(AND(C21="",D21=""),"",IF(OR(C21="",D21=""),"ЗАПОЛНИ ПАРУ",IF(COUNTIFS(ТЕХ_Списки!$A$2:$A$71,C21,ТЕХ_Списки!$B$2:$B$71,D21)<>1,"НЕВЕРНАЯ ПАРА",IF(E21="","РОЛЬ НЕ НАЙДЕНА",IF(AND($R$2<>"Без ограничений",OR(SUMIF(ТЕХ_Расчет!$A$2:$A$26,C21&"§"&D21,ТЕХ_Расчет!$B$2:$B$26)>$T$2,SUMIF($C$6:$C$30,C21,$H$6:$H$30)>$V$2)),"ПРЕВЫШЕН ЛИМИТ","OK"))))) | H21: =IF(OR(C21="",D21=""),0,IF(F21="",1,F21)) -> 0 | I21: Утилити-бафы | J21: 3% Critical Strike (all) | K21: =ТЕХ_Расчет!S$43 -> 0 | L21: =IF(K21=0,"НЕ ХВАТАЕТ",IF(K21=1,"ЕСТЬ","ЕСТЬ ЗАПАС")) -> НЕ ХВАТАЕТ | M21: ='СПРАВОЧНИК ЭФФЕКТОВ'!C19 -> Критично | N21: =IF(M21="Критично",3,IF(M21="Важно",2,IF(M21="Опционально",1,0))) -> 3 | O21: =IFERROR(INDEX(ТЕХ_Подсказки!$BU$2:$BU$46,MATCH(LARGE(ТЕХ_Подсказки!$BX$2:$BX$46,7),ТЕХ_Подсказки!$BX$2:$BX$46,0)),"") -> Критично | P21: =IFERROR(INDEX(ТЕХ_Подсказки!$BT$2:$BT$46,MATCH(LARGE(ТЕХ_Подсказки!$BX$2:$BX$46,7),ТЕХ_Подсказки!$BX$2:$BX$46,0)),"") -> 5% Attack Power | S21: =IFERROR(INDEX(ТЕХ_Подсказки!$BW$2:$BW$46,MATCH(LARGE(ТЕХ_Подсказки!$BX$2:$BX$46,7),ТЕХ_Подсказки!$BX$2:$BX$46,0)),"") -> Bloodmage — Eternal; Guardian — Gladiator; Knight of Xoroth — Hellfire; Primalist — Wildwalker; + ещё 5 классов
A22: 17 | E22: =IF(OR(C22="",D22=""),"",IFERROR(INDEX(ТЕХ_Списки!$C$2:$C$71,MATCH(C22&"§"&D22,ТЕХ_Списки!$D$2:$D$71,0)),"")) | G22: =IF(AND(C22="",D22=""),"",IF(OR(C22="",D22=""),"ЗАПОЛНИ ПАРУ",IF(COUNTIFS(ТЕХ_Списки!$A$2:$A$71,C22,ТЕХ_Списки!$B$2:$B$71,D22)<>1,"НЕВЕРНАЯ ПАРА",IF(E22="","РОЛЬ НЕ НАЙДЕНА",IF(AND($R$2<>"Без ограничений",OR(SUMIF(ТЕХ_Расчет!$A$2:$A$26,C22&"§"&D22,ТЕХ_Расчет!$B$2:$B$26)>$T$2,SUMIF($C$6:$C$30,C22,$H$6:$H$30)>$V$2)),"ПРЕВЫШЕН ЛИМИТ","OK"))))) | H22: =IF(OR(C22="",D22=""),0,IF(F22="",1,F22)) -> 0 | I22: Утилити-бафы | J22: 3% Damage Done (all) | K22: =ТЕХ_Расчет!T$43 -> 0 | L22: =IF(K22=0,"НЕ ХВАТАЕТ",IF(K22=1,"ЕСТЬ","ЕСТЬ ЗАПАС")) -> НЕ ХВАТАЕТ | M22: ='СПРАВОЧНИК ЭФФЕКТОВ'!C20 -> Критично | N22: =IF(M22="Критично",3,IF(M22="Важно",2,IF(M22="Опционально",1,0))) -> 3 | O22: =IFERROR(INDEX(ТЕХ_Подсказки!$BU$2:$BU$46,MATCH(LARGE(ТЕХ_Подсказки!$BX$2:$BX$46,8),ТЕХ_Подсказки!$BX$2:$BX$46,0)),"") -> Критично | P22: =IFERROR(INDEX(ТЕХ_Подсказки!$BT$2:$BT$46,MATCH(LARGE(ТЕХ_Подсказки!$BX$2:$BX$46,8),ТЕХ_Подсказки!$BX$2:$BX$46,0)),"") -> 10% Melee & Range Haste | S22: =IFERROR(INDEX(ТЕХ_Подсказки!$BW$2:$BW$46,MATCH(LARGE(ТЕХ_Подсказки!$BX$2:$BX$46,8),ТЕХ_Подсказки!$BX$2:$BX$46,0)),"") -> Ranger — любой спек; Runemaster — Engravement; Starcaller — Sentinel; Templar — Zealot; + ещё 4 классов
A23: 18 | E23: =IF(OR(C23="",D23=""),"",IFERROR(INDEX(ТЕХ_Списки!$C$2:$C$71,MATCH(C23&"§"&D23,ТЕХ_Списки!$D$2:$D$71,0)),"")) | G23: =IF(AND(C23="",D23=""),"",IF(OR(C23="",D23=""),"ЗАПОЛНИ ПАРУ",IF(COUNTIFS(ТЕХ_Списки!$A$2:$A$71,C23,ТЕХ_Списки!$B$2:$B$71,D23)<>1,"НЕВЕРНАЯ ПАРА",IF(E23="","РОЛЬ НЕ НАЙДЕНА",IF(AND($R$2<>"Без ограничений",OR(SUMIF(ТЕХ_Расчет!$A$2:$A$26,C23&"§"&D23,ТЕХ_Расчет!$B$2:$B$26)>$T$2,SUMIF($C$6:$C$30,C23,$H$6:$H$30)>$V$2)),"ПРЕВЫШЕН ЛИМИТ","OK"))))) | H23: =IF(OR(C23="",D23=""),0,IF(F23="",1,F23)) -> 0 | I23: Утилити-бафы | J23: Small Resistances (all) | K23: =ТЕХ_Расчет!U$43 -> 0 | L23: =IF(K23=0,"НЕ ХВАТАЕТ",IF(K23=1,"ЕСТЬ","ЕСТЬ ЗАПАС")) -> НЕ ХВАТАЕТ | M23: ='СПРАВОЧНИК ЭФФЕКТОВ'!C21 -> Опционально | N23: =IF(M23="Критично",3,IF(M23="Важно",2,IF(M23="Опционально",1,0))) -> 1
A24: 19 | E24: =IF(OR(C24="",D24=""),"",IFERROR(INDEX(ТЕХ_Списки!$C$2:$C$71,MATCH(C24&"§"&D24,ТЕХ_Списки!$D$2:$D$71,0)),"")) | G24: =IF(AND(C24="",D24=""),"",IF(OR(C24="",D24=""),"ЗАПОЛНИ ПАРУ",IF(COUNTIFS(ТЕХ_Списки!$A$2:$A$71,C24,ТЕХ_Списки!$B$2:$B$71,D24)<>1,"НЕВЕРНАЯ ПАРА",IF(E24="","РОЛЬ НЕ НАЙДЕНА",IF(AND($R$2<>"Без ограничений",OR(SUMIF(ТЕХ_Расчет!$A$2:$A$26,C24&"§"&D24,ТЕХ_Расчет!$B$2:$B$26)>$T$2,SUMIF($C$6:$C$30,C24,$H$6:$H$30)>$V$2)),"ПРЕВЫШЕН ЛИМИТ","OK"))))) | H24: =IF(OR(C24="",D24=""),0,IF(F24="",1,F24)) -> 0 | I24: Утилити-бафы | J24: Fire Resistance | K24: =ТЕХ_Расчет!V$43 -> 0 | L24: =IF(K24=0,"НЕ ХВАТАЕТ",IF(K24=1,"ЕСТЬ","ЕСТЬ ЗАПАС")) -> НЕ ХВАТАЕТ | M24: ='СПРАВОЧНИК ЭФФЕКТОВ'!C22 -> Опционально | N24: =IF(M24="Критично",3,IF(M24="Важно",2,IF(M24="Опционально",1,0))) -> 1 | O24: ПРОВЕРИТЬ КОНКРЕТНЫЙ ЭФФЕКТ
A25: 20 | E25: =IF(OR(C25="",D25=""),"",IFERROR(INDEX(ТЕХ_Списки!$C$2:$C$71,MATCH(C25&"§"&D25,ТЕХ_Списки!$D$2:$D$71,0)),"")) | G25: =IF(AND(C25="",D25=""),"",IF(OR(C25="",D25=""),"ЗАПОЛНИ ПАРУ",IF(COUNTIFS(ТЕХ_Списки!$A$2:$A$71,C25,ТЕХ_Списки!$B$2:$B$71,D25)<>1,"НЕВЕРНАЯ ПАРА",IF(E25="","РОЛЬ НЕ НАЙДЕНА",IF(AND($R$2<>"Без ограничений",OR(SUMIF(ТЕХ_Расчет!$A$2:$A$26,C25&"§"&D25,ТЕХ_Расчет!$B$2:$B$26)>$T$2,SUMIF($C$6:$C$30,C25,$H$6:$H$30)>$V$2)),"ПРЕВЫШЕН ЛИМИТ","OK"))))) | H25: =IF(OR(C25="",D25=""),0,IF(F25="",1,F25)) -> 0 | I25: Утилити-бафы | J25: Frost Resistance | K25: =ТЕХ_Расчет!W$43 -> 0 | L25: =IF(K25=0,"НЕ ХВАТАЕТ",IF(K25=1,"ЕСТЬ","ЕСТЬ ЗАПАС")) -> НЕ ХВАТАЕТ | M25: ='СПРАВОЧНИК ЭФФЕКТОВ'!C23 -> Опционально | N25: =IF(M25="Критично",3,IF(M25="Важно",2,IF(M25="Опционально",1,0))) -> 1 | O25: Эффект | U25: Статус | V25: =IFERROR(INDEX('СПРАВОЧНИК ЭФФЕКТОВ'!$E$4:$E$48,MATCH(P25,'СПРАВОЧНИК ЭФФЕКТОВ'!$B$4:$B$48,0)),"")
A26: 21 | E26: =IF(OR(C26="",D26=""),"",IFERROR(INDEX(ТЕХ_Списки!$C$2:$C$71,MATCH(C26&"§"&D26,ТЕХ_Списки!$D$2:$D$71,0)),"")) | G26: =IF(AND(C26="",D26=""),"",IF(OR(C26="",D26=""),"ЗАПОЛНИ ПАРУ",IF(COUNTIFS(ТЕХ_Списки!$A$2:$A$71,C26,ТЕХ_Списки!$B$2:$B$71,D26)<>1,"НЕВЕРНАЯ ПАРА",IF(E26="","РОЛЬ НЕ НАЙДЕНА",IF(AND($R$2<>"Без ограничений",OR(SUMIF(ТЕХ_Расчет!$A$2:$A$26,C26&"§"&D26,ТЕХ_Расчет!$B$2:$B$26)>$T$2,SUMIF($C$6:$C$30,C26,$H$6:$H$30)>$V$2)),"ПРЕВЫШЕН ЛИМИТ","OK"))))) | H26: =IF(OR(C26="",D26=""),0,IF(F26="",1,F26)) -> 0 | I26: Утилити-бафы | J26: Nature Resistance | K26: =ТЕХ_Расчет!X$43 -> 0 | L26: =IF(K26=0,"НЕ ХВАТАЕТ",IF(K26=1,"ЕСТЬ","ЕСТЬ ЗАПАС")) -> НЕ ХВАТАЕТ | M26: ='СПРАВОЧНИК ЭФФЕКТОВ'!C24 -> Опционально | N26: =IF(M26="Критично",3,IF(M26="Важно",2,IF(M26="Опционально",1,0))) -> 1 | O26: Кто закрывает | P26: =IFERROR(INDEX('СПРАВОЧНИК ЭФФЕКТОВ'!$L$4:$L$48,MATCH(P25,'СПРАВОЧНИК ЭФФЕКТОВ'!$B$4:$B$48,0)),"")
A27: 22 | E27: =IF(OR(C27="",D27=""),"",IFERROR(INDEX(ТЕХ_Списки!$C$2:$C$71,MATCH(C27&"§"&D27,ТЕХ_Списки!$D$2:$D$71,0)),"")) | G27: =IF(AND(C27="",D27=""),"",IF(OR(C27="",D27=""),"ЗАПОЛНИ ПАРУ",IF(COUNTIFS(ТЕХ_Списки!$A$2:$A$71,C27,ТЕХ_Списки!$B$2:$B$71,D27)<>1,"НЕВЕРНАЯ ПАРА",IF(E27="","РОЛЬ НЕ НАЙДЕНА",IF(AND($R$2<>"Без ограничений",OR(SUMIF(ТЕХ_Расчет!$A$2:$A$26,C27&"§"&D27,ТЕХ_Расчет!$B$2:$B$26)>$T$2,SUMIF($C$6:$C$30,C27,$H$6:$H$30)>$V$2)),"ПРЕВЫШЕН ЛИМИТ","OK"))))) | H27: =IF(OR(C27="",D27=""),0,IF(F27="",1,F27)) -> 0 | I27: Утилити-бафы | J27: Shadow Resistance | K27: =ТЕХ_Расчет!Y$43 -> 0 | L27: =IF(K27=0,"НЕ ХВАТАЕТ",IF(K27=1,"ЕСТЬ","ЕСТЬ ЗАПАС")) -> НЕ ХВАТАЕТ | M27: ='СПРАВОЧНИК ЭФФЕКТОВ'!C25 -> Опционально | N27: =IF(M27="Критично",3,IF(M27="Важно",2,IF(M27="Опционально",1,0))) -> 1
A28: 23 | E28: =IF(OR(C28="",D28=""),"",IFERROR(INDEX(ТЕХ_Списки!$C$2:$C$71,MATCH(C28&"§"&D28,ТЕХ_Списки!$D$2:$D$71,0)),"")) | G28: =IF(AND(C28="",D28=""),"",IF(OR(C28="",D28=""),"ЗАПОЛНИ ПАРУ",IF(COUNTIFS(ТЕХ_Списки!$A$2:$A$71,C28,ТЕХ_Списки!$B$2:$B$71,D28)<>1,"НЕВЕРНАЯ ПАРА",IF(E28="","РОЛЬ НЕ НАЙДЕНА",IF(AND($R$2<>"Без ограничений",OR(SUMIF(ТЕХ_Расчет!$A$2:$A$26,C28&"§"&D28,ТЕХ_Расчет!$B$2:$B$26)>$T$2,SUMIF($C$6:$C$30,C28,$H$6:$H$30)>$V$2)),"ПРЕВЫШЕН ЛИМИТ","OK"))))) | H28: =IF(OR(C28="",D28=""),0,IF(F28="",1,F28)) -> 0 | I28: Утилити-бафы | J28: Arcane Resistance | K28: =ТЕХ_Расчет!Z$43 -> 0 | L28: =IF(K28=0,"НЕ ХВАТАЕТ",IF(K28=1,"ЕСТЬ","ЕСТЬ ЗАПАС")) -> НЕ ХВАТАЕТ | M28: ='СПРАВОЧНИК ЭФФЕКТОВ'!C26 -> Опционально | N28: =IF(M28="Критично",3,IF(M28="Важно",2,IF(M28="Опционально",1,0))) -> 1 | O28: БАЛАНС РОЛЕЙ | S28: БЫСТРЫЕ УБИЙСТВА
A29: 24 | E29: =IF(OR(C29="",D29=""),"",IFERROR(INDEX(ТЕХ_Списки!$C$2:$C$71,MATCH(C29&"§"&D29,ТЕХ_Списки!$D$2:$D$71,0)),"")) | G29: =IF(AND(C29="",D29=""),"",IF(OR(C29="",D29=""),"ЗАПОЛНИ ПАРУ",IF(COUNTIFS(ТЕХ_Списки!$A$2:$A$71,C29,ТЕХ_Списки!$B$2:$B$71,D29)<>1,"НЕВЕРНАЯ ПАРА",IF(E29="","РОЛЬ НЕ НАЙДЕНА",IF(AND($R$2<>"Без ограничений",OR(SUMIF(ТЕХ_Расчет!$A$2:$A$26,C29&"§"&D29,ТЕХ_Расчет!$B$2:$B$26)>$T$2,SUMIF($C$6:$C$30,C29,$H$6:$H$30)>$V$2)),"ПРЕВЫШЕН ЛИМИТ","OK"))))) | H29: =IF(OR(C29="",D29=""),0,IF(F29="",1,F29)) -> 0 | I29: Утилити-бафы | J29: 5% Resource Reduction | K29: =ТЕХ_Расчет!AA$43 -> 0 | L29: =IF(K29=0,"НЕ ХВАТАЕТ",IF(K29=1,"ЕСТЬ","ЕСТЬ ЗАПАС")) -> НЕ ХВАТАЕТ | M29: ='СПРАВОЧНИК ЭФФЕКТОВ'!C27 -> Опционально | N29: =IF(M29="Критично",3,IF(M29="Важно",2,IF(M29="Опционально",1,0))) -> 1 | O29: Роль | P29: Цель | Q29: Сейчас | R29: Нужно | S29: Рейды ровно на 25: медиана быстрых убийств — 2 танка / 4 хила / 1 саппорт / 18 DPS. Выборка 20–30: 2 / 3 / 2 / 17. Поэтому 3 хила — скоростной профиль, 4 — универсальный. Второй саппорт ценен, пока закрывает критические/важные эффекты; после этого соревнуется с DPS по логам.
A30: 25 | E30: =IF(OR(C30="",D30=""),"",IFERROR(INDEX(ТЕХ_Списки!$C$2:$C$71,MATCH(C30&"§"&D30,ТЕХ_Списки!$D$2:$D$71,0)),"")) | G30: =IF(AND(C30="",D30=""),"",IF(OR(C30="",D30=""),"ЗАПОЛНИ ПАРУ",IF(COUNTIFS(ТЕХ_Списки!$A$2:$A$71,C30,ТЕХ_Списки!$B$2:$B$71,D30)<>1,"НЕВЕРНАЯ ПАРА",IF(E30="","РОЛЬ НЕ НАЙДЕНА",IF(AND($R$2<>"Без ограничений",OR(SUMIF(ТЕХ_Расчет!$A$2:$A$26,C30&"§"&D30,ТЕХ_Расчет!$B$2:$B$26)>$T$2,SUMIF($C$6:$C$30,C30,$H$6:$H$30)>$V$2)),"ПРЕВЫШЕН ЛИМИТ","OK"))))) | H30: =IF(OR(C30="",D30=""),0,IF(F30="",1,F30)) -> 0 | I30: Утилити-бафы | J30: 3% Damage Reduction (all) | K30: =ТЕХ_Расчет!AB$43 -> 0 | L30: =IF(K30=0,"НЕ ХВАТАЕТ",IF(K30=1,"ЕСТЬ","ЕСТЬ ЗАПАС")) -> НЕ ХВАТАЕТ | M30: ='СПРАВОЧНИК ЭФФЕКТОВ'!C28 -> Критично | N30: =IF(M30="Критично",3,IF(M30="Важно",2,IF(M30="Опционально",1,0))) -> 3 | O30: Танк | P30: =2 -> 2 | Q30: =SUMIFS($H$6:$H$30,$E$6:$E$30,O30) -> 0 | R30: =MAX(P30-Q30,0) -> 2
A31: ИТОГО ПО СОСТАВУ | G31: =IF(H31=$R$3,"25 ИЗ 25",IF(H31<$R$3,"ОСТАЛОСЬ "&($R$3-H31),"ЛИШНИХ "&(H31-$R$3))) -> ОСТАЛОСЬ 25 | H31: =SUM(H6:H30) -> 0 | I31: Утилити-бафы | J31: 6% Healing Done | K31: =ТЕХ_Расчет!AC$43 -> 0 | L31: =IF(K31=0,"НЕ ХВАТАЕТ",IF(K31=1,"ЕСТЬ","ЕСТЬ ЗАПАС")) -> НЕ ХВАТАЕТ | M31: ='СПРАВОЧНИК ЭФФЕКТОВ'!C29 -> Опционально | N31: =IF(M31="Критично",3,IF(M31="Важно",2,IF(M31="Опционально",1,0))) -> 1 | O31: Хилер | P31: =IF($P$2="Скорость",3,IF($P$2="Универсальный",4,5)) -> 5 | Q31: =SUMIFS($H$6:$H$30,$E$6:$E$30,O31) -> 0 | R31: =MAX(P31-Q31,0) -> 5
A32: Ниже — расчётные рекомендации. Эти строки не являются участниками рейда и не влияют на покрытие. | I32: Утилити-бафы | J32: Concentration | K32: =ТЕХ_Расчет!AD$43 -> 0 | L32: =IF(K32=0,"НЕ ХВАТАЕТ",IF(K32=1,"ЕСТЬ","ЕСТЬ ЗАПАС")) -> НЕ ХВАТАЕТ | M32: ='СПРАВОЧНИК ЭФФЕКТОВ'!C30 -> Опционально | N32: =IF(M32="Критично",3,IF(M32="Важно",2,IF(M32="Опционально",1,0))) -> 1 | O32: Саппорт | P32: =IF($P$2="Скорость",1,2) -> 2 | Q32: =SUMIFS($H$6:$H$30,$E$6:$E$30,O32) -> 0 | R32: =MAX(P32-Q32,0) -> 2
A33: ТОП-10 СЛЕДУЮЩИХ СЛОТОВ — ПОЛНЫЙ РЕЙТИНГ | I33: Утилити-бафы | J33: Amplify Magic | K33: =ТЕХ_Расчет!AE$43 -> 0 | L33: =IF(K33=0,"НЕ ХВАТАЕТ",IF(K33=1,"ЕСТЬ","ЕСТЬ ЗАПАС")) -> НЕ ХВАТАЕТ | M33: ='СПРАВОЧНИК ЭФФЕКТОВ'!C31 -> Опционально | N33: =IF(M33="Критично",3,IF(M33="Важно",2,IF(M33="Опционально",1,0))) -> 1 | O33: DPS | P33: =$R$3-SUM(P30:P32) -> 16 | Q33: =SUM($H$6:$H$30)-SUM(Q30:Q32) -> 0 | R33: =MAX(P33-Q33,0) -> 16
A34: № | B34: Класс | C34: Специализация | D34: Роль | E34: Крит. | F34: Важн. | G34: Логи | H34: Итог | I34: Утилити-бафы | J34: Dampen Magic | K34: =ТЕХ_Расчет!AF$43 -> 0 | L34: =IF(K34=0,"НЕ ХВАТАЕТ",IF(K34=1,"ЕСТЬ","ЕСТЬ ЗАПАС")) -> НЕ ХВАТАЕТ | M34: ='СПРАВОЧНИК ЭФФЕКТОВ'!C32 -> Опционально | N34: =IF(M34="Критично",3,IF(M34="Важно",2,IF(M34="Опционально",1,0))) -> 1
A35: 1 | B35: =IFERROR(INDEX(ТЕХ_Подсказки!$A$2:$V$71,$N55,1),"") -> Felsworn | C35: =IFERROR(INDEX(ТЕХ_Подсказки!$A$2:$V$71,$N55,2),"") -> Tyrant | D35: =IFERROR(INDEX(ТЕХ_Подсказки!$A$2:$V$71,$N55,3),"") -> Танк | E35: =IFERROR(INDEX(ТЕХ_Подсказки!$A$2:$V$71,$N55,13),"") -> 0 | F35: =IFERROR(INDEX(ТЕХ_Подсказки!$A$2:$V$71,$N55,14),"") -> 0 | G35: =IFERROR(INDEX(ТЕХ_Подсказки!$A$2:$V$71,$N55,9),"") -> 88.24 | H35: =IFERROR(INDEX(ТЕХ_Подсказки!$A$2:$V$71,$N55,19),"") -> 158.24 | I35: Утилити-бафы | J35: Armor | K35: =ТЕХ_Расчет!AG$43 -> 0 | L35: =IF(K35=0,"НЕ ХВАТАЕТ",IF(K35=1,"ЕСТЬ","ЕСТЬ ЗАПАС")) -> НЕ ХВАТАЕТ | M35: ='СПРАВОЧНИК ЭФФЕКТОВ'!C33 -> Критично | N35: =IF(M35="Критично",3,IF(M35="Важно",2,IF(M35="Опционально",1,0))) -> 3
A36: 2 | B36: =IFERROR(INDEX(ТЕХ_Подсказки!$A$2:$V$71,$N56,1),"") -> Pyromancer | C36: =IFERROR(INDEX(ТЕХ_Подсказки!$A$2:$V$71,$N56,2),"") -> Flameweaving | D36: =IFERROR(INDEX(ТЕХ_Подсказки!$A$2:$V$71,$N56,3),"") -> Хилер | E36: =IFERROR(INDEX(ТЕХ_Подсказки!$A$2:$V$71,$N56,13),"") -> 0 | F36: =IFERROR(INDEX(ТЕХ_Подсказки!$A$2:$V$71,$N56,14),"") -> 0 | G36: =IFERROR(INDEX(ТЕХ_Подсказки!$A$2:$V$71,$N56,9),"") -> 94.51 | H36: =IFERROR(INDEX(ТЕХ_Подсказки!$A$2:$V$71,$N56,19),"") -> 149.51 | I36: Утилити-бафы | J36: Defensive Cooldown (Raid-Wide) | K36: =ТЕХ_Расчет!AH$43 -> 0 | L36: =IF(K36=0,"НЕ ХВАТАЕТ",IF(K36=1,"ЕСТЬ","ЕСТЬ ЗАПАС")) -> НЕ ХВАТАЕТ | M36: ='СПРАВОЧНИК ЭФФЕКТОВ'!C34 -> Критично | N36: =IF(M36="Критично",3,IF(M36="Важно",2,IF(M36="Опционально",1,0))) -> 3
A37: 3 | B37: =IFERROR(INDEX(ТЕХ_Подсказки!$A$2:$V$71,$N57,1),"") -> Primalist | C37: =IFERROR(INDEX(ТЕХ_Подсказки!$A$2:$V$71,$N57,2),"") -> Mountain King | D37: =IFERROR(INDEX(ТЕХ_Подсказки!$A$2:$V$71,$N57,3),"") -> Танк | E37: =IFERROR(INDEX(ТЕХ_Подсказки!$A$2:$V$71,$N57,13),"") -> 0 | F37: =IFERROR(INDEX(ТЕХ_Подсказки!$A$2:$V$71,$N57,14),"") -> 0 | G37: =IFERROR(INDEX(ТЕХ_Подсказки!$A$2:$V$71,$N57,9),"") -> 75.84 | H37: =IFERROR(INDEX(ТЕХ_Подсказки!$A$2:$V$71,$N57,19),"") -> 145.84 | I37: Утилити-бафы | J37: Heroism | Bloodlust | K37: =ТЕХ_Расчет!AI$43 -> 0 | L37: =IF(K37=0,"НЕ ХВАТАЕТ",IF(K37=1,"ЕСТЬ","ЕСТЬ ЗАПАС")) -> НЕ ХВАТАЕТ | M37: ='СПРАВОЧНИК ЭФФЕКТОВ'!C35 -> Критично | N37: =IF(M37="Критично",3,IF(M37="Важно",2,IF(M37="Опционально",1,0))) -> 3
A38: 4 | B38: =IFERROR(INDEX(ТЕХ_Подсказки!$A$2:$V$71,$N58,1),"") -> Venomancer | C38: =IFERROR(INDEX(ТЕХ_Подсказки!$A$2:$V$71,$N58,2),"") -> Fortitude | D38: =IFERROR(INDEX(ТЕХ_Подсказки!$A$2:$V$71,$N58,3),"") -> Танк | E38: =IFERROR(INDEX(ТЕХ_Подсказки!$A$2:$V$71,$N58,13),"") -> 0 | F38: =IFERROR(INDEX(ТЕХ_Подсказки!$A$2:$V$71,$N58,14),"") -> 0 | G38: =IFERROR(INDEX(ТЕХ_Подсказки!$A$2:$V$71,$N58,9),"") -> 73.36 | H38: =IFERROR(INDEX(ТЕХ_Подсказки!$A$2:$V$71,$N58,19),"") -> 143.36 | I38: Физические дебафы | J38: 4% Physical Damage | K38: =ТЕХ_Расчет!AJ$43 -> 0 | L38: =IF(K38=0,"НЕ ХВАТАЕТ",IF(K38=1,"ЕСТЬ","ЕСТЬ ЗАПАС")) -> НЕ ХВАТАЕТ | M38: ='СПРАВОЧНИК ЭФФЕКТОВ'!C36 -> Критично | N38: =IF(M38="Критично",3,IF(M38="Важно",2,IF(M38="Опционально",1,0))) -> 3
A39: 5 | B39: =IFERROR(INDEX(ТЕХ_Подсказки!$A$2:$V$71,$N59,1),"") -> Cultist | C39: =IFERROR(INDEX(ТЕХ_Подсказки!$A$2:$V$71,$N59,2),"") -> Heretic | D39: =IFERROR(INDEX(ТЕХ_Подсказки!$A$2:$V$71,$N59,3),"") -> Хилер | E39: =IFERROR(INDEX(ТЕХ_Подсказки!$A$2:$V$71,$N59,13),"") -> 0 | F39: =IFERROR(INDEX(ТЕХ_Подсказки!$A$2:$V$71,$N59,14),"") -> 0 | G39: =IFERROR(INDEX(ТЕХ_Подсказки!$A$2:$V$71,$N59,9),"") -> 88.03 | H39: =IFERROR(INDEX(ТЕХ_Подсказки!$A$2:$V$71,$N59,19),"") -> 143.03 | I39: Физические дебафы | J39: 30% Bleed Damage | K39: =ТЕХ_Расчет!AK$43 -> 0 | L39: =IF(K39=0,"НЕ ХВАТАЕТ",IF(K39=1,"ЕСТЬ","ЕСТЬ ЗАПАС")) -> НЕ ХВАТАЕТ | M39: ='СПРАВОЧНИК ЭФФЕКТОВ'!C37 -> Опционально | N39: =IF(M39="Критично",3,IF(M39="Важно",2,IF(M39="Опционально",1,0))) -> 1
A40: 6 | B40: =IFERROR(INDEX(ТЕХ_Подсказки!$A$2:$V$71,$N60,1),"") -> Bloodmage | C40: =IFERROR(INDEX(ТЕХ_Подсказки!$A$2:$V$71,$N60,2),"") -> Fleshweaver | D40: =IFERROR(INDEX(ТЕХ_Подсказки!$A$2:$V$71,$N60,3),"") -> Саппорт | E40: =IFERROR(INDEX(ТЕХ_Подсказки!$A$2:$V$71,$N60,13),"") -> 0 | F40: =IFERROR(INDEX(ТЕХ_Подсказки!$A$2:$V$71,$N60,14),"") -> 0 | G40: =IFERROR(INDEX(ТЕХ_Подсказки!$A$2:$V$71,$N60,9),"") -> 92.75 | H40: =IFERROR(INDEX(ТЕХ_Подсказки!$A$2:$V$71,$N60,19),"") -> 142.75 | I40: Физические дебафы | J40: Armor Reduction | K40: =ТЕХ_Расчет!AL$43 -> 0 | L40: =IF(K40=0,"НЕ ХВАТАЕТ",IF(K40=1,"ЕСТЬ","ЕСТЬ ЗАПАС")) -> НЕ ХВАТАЕТ | M40: ='СПРАВОЧНИК ЭФФЕКТОВ'!C38 -> Критично | N40: =IF(M40="Критично",3,IF(M40="Важно",2,IF(M40="Опционально",1,0))) -> 3
...

Sheet СРАВНЕНИЕ СПЕКОВ
A1: СРАВНЕНИЕ ДВУХ СПЕКОВ ДЛЯ ТЕКУЩЕГО РЕЙДА
A2: Выбери два варианта. Сравнение учитывает уже заполненный состав на листе «РЕЙД-КОНСТРУКТОР» и показывает, какой вариант закроет больше приоритетных пробелов.
A4: ВАРИАНТ A | E4: ВАРИАНТ B
A5: Класс | B5: Felsworn | E5: Класс | F5: Ranger
A6: Специализация | B6: Infernal | E6: Специализация | F6: Brigand
A7: Роль | B7: =IF(OR(B5="",B6=""),"",IFERROR(INDEX(ТЕХ_Списки!$C$2:$C$71,MATCH(B5&"§"&B6,ТЕХ_Списки!$D$2:$D$71,0)),"")) -> Рейндж/кастер | E7: Роль | F7: =IF(OR(F5="",F6=""),"",IFERROR(INDEX(ТЕХ_Списки!$C$2:$C$71,MATCH(F5&"§"&F6,ТЕХ_Списки!$D$2:$D$71,0)),"")) -> Мили-DPS
A8: Новых эффектов | B8: =IF(OR(B5="",B6=""),0,COUNTIFS($C$15:$C$59,0,$D$15:$D$59,"✓")) -> 8 | E8: Новых эффектов | F8: =IF(OR(F5="",F6=""),0,COUNTIFS($C$15:$C$59,0,$E$15:$E$59,"✓")) -> 6
A9: Приоритетный балл | B9: =IF(OR(B5="",B6=""),0,SUMPRODUCT(--($C$15:$C$59=0),--($D$15:$D$59="✓"),$H$15:$H$59)) -> 18 | E9: Приоритетный балл | F9: =IF(OR(F5="",F6=""),0,SUMPRODUCT(--($C$15:$C$59=0),--($E$15:$E$59="✓"),$H$15:$H$59)) -> 10
A10: Всего эффектов | B10: =IF(OR(B5="",B6=""),0,COUNTIF($D$15:$D$59,"✓")) -> 8 | E10: Всего эффектов | F10: =IF(OR(F5="",F6=""),0,COUNTIF($E$15:$E$59,"✓")) -> 6
A12: =IF(OR(B5="",B6="",F5="",F6=""),"Выбери оба варианта",IF(B9>F9,"ЛУЧШЕ ВАРИАНТ A: "&B5&" — "&B6,IF(F9>B9,"ЛУЧШЕ ВАРИАНТ B: "&F5&" — "&F6,IF(B8>F8,"ЛУЧШЕ ВАРИАНТ A: "&B5&" — "&B6,IF(F8>B8,"ЛУЧШЕ ВАРИАНТ B: "&F5&" — "&F6,"РАВНОЦЕННО ДЛЯ ТЕКУЩЕГО РЕЙДА"))))) -> ЛУЧШЕ ВАРИАНТ A: Felsworn — Infernal
A14: Категория | B14: Эффект | C14: В рейде | D14: Вариант A | E14: Вариант B | F14: Разница | G14: Приоритет | H14: Вес
A15: Физические бафы | B15: 10% Stats | C15: ='РЕЙД-КОНСТРУКТОР'!K6 -> 0 | D15: =IF(OR($B$5="",$B$6=""),"—",IF(IFERROR(INDEX(ТЕХ_Списки!$E$2:$E$71,MATCH($B$5&"§"&$B$6,ТЕХ_Списки!$D$2:$D$71,0)),0)=1,"✓","—")) -> — | E15: =IF(OR($F$5="",$F$6=""),"—",IF(IFERROR(INDEX(ТЕХ_Списки!$E$2:$E$71,MATCH($F$5&"§"&$F$6,ТЕХ_Списки!$D$2:$D$71,0)),0)=1,"✓","—")) -> — | F15: =IF(D15=E15,"Одинаково",IF(D15="✓","Только A","Только B")) -> Одинаково | G15: ='РЕЙД-КОНСТРУКТОР'!M6 -> Критично | H15: ='РЕЙД-КОНСТРУКТОР'!N6 -> 3
A16: Физические бафы | B16: Minor Armor and All Stats | C16: ='РЕЙД-КОНСТРУКТОР'!K7 -> 0 | D16: =IF(OR($B$5="",$B$6=""),"—",IF(IFERROR(INDEX(ТЕХ_Списки!$F$2:$F$71,MATCH($B$5&"§"&$B$6,ТЕХ_Списки!$D$2:$D$71,0)),0)=1,"✓","—")) -> ✓ | E16: =IF(OR($F$5="",$F$6=""),"—",IF(IFERROR(INDEX(ТЕХ_Списки!$F$2:$F$71,MATCH($F$5&"§"&$F$6,ТЕХ_Списки!$D$2:$D$71,0)),0)=1,"✓","—")) -> ✓ | F16: =IF(D16=E16,"Одинаково",IF(D16="✓","Только A","Только B")) -> Одинаково | G16: ='РЕЙД-КОНСТРУКТОР'!M7 -> Важно | H16: ='РЕЙД-КОНСТРУКТОР'!N7 -> 2
A17: Физические бафы | B17: Stamina | C17: ='РЕЙД-КОНСТРУКТОР'!K8 -> 0 | D17: =IF(OR($B$5="",$B$6=""),"—",IF(IFERROR(INDEX(ТЕХ_Списки!$G$2:$G$71,MATCH($B$5&"§"&$B$6,ТЕХ_Списки!$D$2:$D$71,0)),0)=1,"✓","—")) -> — | E17: =IF(OR($F$5="",$F$6=""),"—",IF(IFERROR(INDEX(ТЕХ_Списки!$G$2:$G$71,MATCH($F$5&"§"&$F$6,ТЕХ_Списки!$D$2:$D$71,0)),0)=1,"✓","—")) -> — | F17: =IF(D17=E17,"Одинаково",IF(D17="✓","Только A","Только B")) -> Одинаково | G17: ='РЕЙД-КОНСТРУКТОР'!M8 -> Важно | H17: ='РЕЙД-КОНСТРУКТОР'!N8 -> 2
A18: Физические бафы | B18: Strength | C18: ='РЕЙД-КОНСТРУКТОР'!K9 -> 0 | D18: =IF(OR($B$5="",$B$6=""),"—",IF(IFERROR(INDEX(ТЕХ_Списки!$H$2:$H$71,MATCH($B$5&"§"&$B$6,ТЕХ_Списки!$D$2:$D$71,0)),0)=1,"✓","—")) -> — | E18: =IF(OR($F$5="",$F$6=""),"—",IF(IFERROR(INDEX(ТЕХ_Списки!$H$2:$H$71,MATCH($F$5&"§"&$F$6,ТЕХ_Списки!$D$2:$D$71,0)),0)=1,"✓","—")) -> — | F18: =IF(D18=E18,"Одинаково",IF(D18="✓","Только A","Только B")) -> Одинаково | G18: ='РЕЙД-КОНСТРУКТОР'!M9 -> Важно | H18: ='РЕЙД-КОНСТРУКТОР'!N9 -> 2
A19: Физические бафы | B19: Agility | C19: ='РЕЙД-КОНСТРУКТОР'!K10 -> 0 | D19: =IF(OR($B$5="",$B$6=""),"—",IF(IFERROR(INDEX(ТЕХ_Списки!$I$2:$I$71,MATCH($B$5&"§"&$B$6,ТЕХ_Списки!$D$2:$D$71,0)),0)=1,"✓","—")) -> — | E19: =IF(OR($F$5="",$F$6=""),"—",IF(IFERROR(INDEX(ТЕХ_Списки!$I$2:$I$71,MATCH($F$5&"§"&$F$6,ТЕХ_Списки!$D$2:$D$71,0)),0)=1,"✓","—")) -> ✓ | F19: =IF(D19=E19,"Одинаково",IF(D19="✓","Только A","Только B")) -> Только B | G19: ='РЕЙД-КОНСТРУКТОР'!M10 -> Важно | H19: ='РЕЙД-КОНСТРУКТОР'!N10 -> 2
A20: Физические бафы | B20: Attack Power | C20: ='РЕЙД-КОНСТРУКТОР'!K11 -> 0 | D20: =IF(OR($B$5="",$B$6=""),"—",IF(IFERROR(INDEX(ТЕХ_Списки!$J$2:$J$71,MATCH($B$5&"§"&$B$6,ТЕХ_Списки!$D$2:$D$71,0)),0)=1,"✓","—")) -> ✓ | E20: =IF(OR($F$5="",$F$6=""),"—",IF(IFERROR(INDEX(ТЕХ_Списки!$J$2:$J$71,MATCH($F$5&"§"&$F$6,ТЕХ_Списки!$D$2:$D$71,0)),0)=1,"✓","—")) -> — | F20: =IF(D20=E20,"Одинаково",IF(D20="✓","Только A","Только B")) -> Только A | G20: ='РЕЙД-КОНСТРУКТОР'!M11 -> Важно | H20: ='РЕЙД-КОНСТРУКТОР'!N11 -> 2
A21: Физические бафы | B21: 5% Attack Power | C21: ='РЕЙД-КОНСТРУКТОР'!K12 -> 0 | D21: =IF(OR($B$5="",$B$6=""),"—",IF(IFERROR(INDEX(ТЕХ_Списки!$K$2:$K$71,MATCH($B$5&"§"&$B$6,ТЕХ_Списки!$D$2:$D$71,0)),0)=1,"✓","—")) -> — | E21: =IF(OR($F$5="",$F$6=""),"—",IF(IFERROR(INDEX(ТЕХ_Списки!$K$2:$K$71,MATCH($F$5&"§"&$F$6,ТЕХ_Списки!$D$2:$D$71,0)),0)=1,"✓","—")) -> — | F21: =IF(D21=E21,"Одинаково",IF(D21="✓","Только A","Только B")) -> Одинаково | G21: ='РЕЙД-КОНСТРУКТОР'!M12 -> Критично | H21: ='РЕЙД-КОНСТРУКТОР'!N12 -> 3
A22: Физические бафы | B22: 10% Melee & Range Haste | C22: ='РЕЙД-КОНСТРУКТОР'!K13 -> 0 | D22: =IF(OR($B$5="",$B$6=""),"—",IF(IFERROR(INDEX(ТЕХ_Списки!$L$2:$L$71,MATCH($B$5&"§"&$B$6,ТЕХ_Списки!$D$2:$D$71,0)),0)=1,"✓","—")) -> — | E22: =IF(OR($F$5="",$F$6=""),"—",IF(IFERROR(INDEX(ТЕХ_Списки!$L$2:$L$71,MATCH($F$5&"§"&$F$6,ТЕХ_Списки!$D$2:$D$71,0)),0)=1,"✓","—")) -> ✓ | F22: =IF(D22=E22,"Одинаково",IF(D22="✓","Только A","Только B")) -> Только B | G22: ='РЕЙД-КОНСТРУКТОР'!M13 -> Критично | H22: ='РЕЙД-КОНСТРУКТОР'!N13 -> 3
A23: Кастерские бафы | B23: Intellect | C23: ='РЕЙД-КОНСТРУКТОР'!K14 -> 0 | D23: =IF(OR($B$5="",$B$6=""),"—",IF(IFERROR(INDEX(ТЕХ_Списки!$M$2:$M$71,MATCH($B$5&"§"&$B$6,ТЕХ_Списки!$D$2:$D$71,0)),0)=1,"✓","—")) -> — | E23: =IF(OR($F$5="",$F$6=""),"—",IF(IFERROR(INDEX(ТЕХ_Списки!$M$2:$M$71,MATCH($F$5&"§"&$F$6,ТЕХ_Списки!$D$2:$D$71,0)),0)=1,"✓","—")) -> — | F23: =IF(D23=E23,"Одинаково",IF(D23="✓","Только A","Только B")) -> Одинаково | G23: ='РЕЙД-КОНСТРУКТОР'!M14 -> Важно | H23: ='РЕЙД-КОНСТРУКТОР'!N14 -> 2
A24: Кастерские бафы | B24: Spirit | C24: ='РЕЙД-КОНСТРУКТОР'!K15 -> 0 | D24: =IF(OR($B$5="",$B$6=""),"—",IF(IFERROR(INDEX(ТЕХ_Списки!$N$2:$N$71,MATCH($B$5&"§"&$B$6,ТЕХ_Списки!$D$2:$D$71,0)),0)=1,"✓","—")) -> — | E24: =IF(OR($F$5="",$F$6=""),"—",IF(IFERROR(INDEX(ТЕХ_Списки!$N$2:$N$71,MATCH($F$5&"§"&$F$6,ТЕХ_Списки!$D$2:$D$71,0)),0)=1,"✓","—")) -> — | F24: =IF(D24=E24,"Одинаково",IF(D24="✓","Только A","Только B")) -> Одинаково | G24: ='РЕЙД-КОНСТРУКТОР'!M15 -> Важно | H24: ='РЕЙД-КОНСТРУКТОР'!N15 -> 2
A25: Кастерские бафы | B25: Spell Power | C25: ='РЕЙД-КОНСТРУКТОР'!K16 -> 0 | D25: =IF(OR($B$5="",$B$6=""),"—",IF(IFERROR(INDEX(ТЕХ_Списки!$O$2:$O$71,MATCH($B$5&"§"&$B$6,ТЕХ_Списки!$D$2:$D$71,0)),0)=1,"✓","—")) -> — | E25: =IF(OR($F$5="",$F$6=""),"—",IF(IFERROR(INDEX(ТЕХ_Списки!$O$2:$O$71,MATCH($F$5&"§"&$F$6,ТЕХ_Списки!$D$2:$D$71,0)),0)=1,"✓","—")) -> — | F25: =IF(D25=E25,"Одинаково",IF(D25="✓","Только A","Только B")) -> Одинаково | G25: ='РЕЙД-КОНСТРУКТОР'!M16 -> Важно | H25: ='РЕЙД-КОНСТРУКТОР'!N16 -> 2
A26: Кастерские бафы | B26: 3% Spell Haste | C26: ='РЕЙД-КОНСТРУКТОР'!K17 -> 0 | D26: =IF(OR($B$5="",$B$6=""),"—",IF(IFERROR(INDEX(ТЕХ_Списки!$P$2:$P$71,MATCH($B$5&"§"&$B$6,ТЕХ_Списки!$D$2:$D$71,0)),0)=1,"✓","—")) -> — | E26: =IF(OR($F$5="",$F$6=""),"—",IF(IFERROR(INDEX(ТЕХ_Списки!$P$2:$P$71,MATCH($F$5&"§"&$F$6,ТЕХ_Списки!$D$2:$D$71,0)),0)=1,"✓","—")) -> — | F26: =IF(D26=E26,"Одинаково",IF(D26="✓","Только A","Только B")) -> Одинаково | G26: ='РЕЙД-КОНСТРУКТОР'!M17 -> Критично | H26: ='РЕЙД-КОНСТРУКТОР'!N17 -> 3
A27: Кастерские бафы | B27: Mana Regeneration | C27: ='РЕЙД-КОНСТРУКТОР'!K18 -> 0 | D27: =IF(OR($B$5="",$B$6=""),"—",IF(IFERROR(INDEX(ТЕХ_Списки!$Q$2:$Q$71,MATCH($B$5&"§"&$B$6,ТЕХ_Списки!$D$2:$D$71,0)),0)=1,"✓","—")) -> — | E27: =IF(OR($F$5="",$F$6=""),"—",IF(IFERROR(INDEX(ТЕХ_Списки!$Q$2:$Q$71,MATCH($F$5&"§"&$F$6,ТЕХ_Списки!$D$2:$D$71,0)),0)=1,"✓","—")) -> — | F27: =IF(D27=E27,"Одинаково",IF(D27="✓","Только A","Только B")) -> Одинаково | G27: ='РЕЙД-КОНСТРУКТОР'!M18 -> Важно | H27: ='РЕЙД-КОНСТРУКТОР'!N18 -> 2
A28: Кастерские бафы | B28: Replenishment | C28: ='РЕЙД-КОНСТРУКТОР'!K19 -> 0 | D28: =IF(OR($B$5="",$B$6=""),"—",IF(IFERROR(INDEX(ТЕХ_Списки!$R$2:$R$71,MATCH($B$5&"§"&$B$6,ТЕХ_Списки!$D$2:$D$71,0)),0)=1,"✓","—")) -> — | E28: =IF(OR($F$5="",$F$6=""),"—",IF(IFERROR(INDEX(ТЕХ_Списки!$R$2:$R$71,MATCH($F$5&"§"&$F$6,ТЕХ_Списки!$D$2:$D$71,0)),0)=1,"✓","—")) -> — | F28: =IF(D28=E28,"Одинаково",IF(D28="✓","Только A","Только B")) -> Одинаково | G28: ='РЕЙД-КОНСТРУКТОР'!M19 -> Критично | H28: ='РЕЙД-КОНСТРУКТОР'!N19 -> 3
A29: Кастерские бафы | B29: Strong Mana Cooldown | C29: ='РЕЙД-КОНСТРУКТОР'!K20 -> 0 | D29: =IF(OR($B$5="",$B$6=""),"—",IF(IFERROR(INDEX(ТЕХ_Списки!$S$2:$S$71,MATCH($B$5&"§"&$B$6,ТЕХ_Списки!$D$2:$D$71,0)),0)=1,"✓","—")) -> — | E29: =IF(OR($F$5="",$F$6=""),"—",IF(IFERROR(INDEX(ТЕХ_Списки!$S$2:$S$71,MATCH($F$5&"§"&$F$6,ТЕХ_Списки!$D$2:$D$71,0)),0)=1,"✓","—")) -> — | F29: =IF(D29=E29,"Одинаково",IF(D29="✓","Только A","Только B")) -> Одинаково | G29: ='РЕЙД-КОНСТРУКТОР'!M20 -> Опционально | H29: ='РЕЙД-КОНСТРУКТОР'!N20 -> 1
A30: Утилити-бафы | B30: 3% Critical Strike (all) | C30: ='РЕЙД-КОНСТРУКТОР'!K21 -> 0 | D30: =IF(OR($B$5="",$B$6=""),"—",IF(IFERROR(INDEX(ТЕХ_Списки!$T$2:$T$71,MATCH($B$5&"§"&$B$6,ТЕХ_Списки!$D$2:$D$71,0)),0)=1,"✓","—")) -> ✓ | E30: =IF(OR($F$5="",$F$6=""),"—",IF(IFERROR(INDEX(ТЕХ_Списки!$T$2:$T$71,MATCH($F$5&"§"&$F$6,ТЕХ_Списки!$D$2:$D$71,0)),0)=1,"✓","—")) -> — | F30: =IF(D30=E30,"Одинаково",IF(D30="✓","Только A","Только B")) -> Только A | G30: ='РЕЙД-КОНСТРУКТОР'!M21 -> Критично | H30: ='РЕЙД-КОНСТРУКТОР'!N21 -> 3
A31: Утилити-бафы | B31: 3% Damage Done (all) | C31: ='РЕЙД-КОНСТРУКТОР'!K22 -> 0 | D31: =IF(OR($B$5="",$B$6=""),"—",IF(IFERROR(INDEX(ТЕХ_Списки!$U$2:$U$71,MATCH($B$5&"§"&$B$6,ТЕХ_Списки!$D$2:$D$71,0)),0)=1,"✓","—")) -> — | E31: =IF(OR($F$5="",$F$6=""),"—",IF(IFERROR(INDEX(ТЕХ_Списки!$U$2:$U$71,MATCH($F$5&"§"&$F$6,ТЕХ_Списки!$D$2:$D$71,0)),0)=1,"✓","—")) -> — | F31: =IF(D31=E31,"Одинаково",IF(D31="✓","Только A","Только B")) -> Одинаково | G31: ='РЕЙД-КОНСТРУКТОР'!M22 -> Критично | H31: ='РЕЙД-КОНСТРУКТОР'!N22 -> 3
A32: Утилити-бафы | B32: Small Resistances (all) | C32: ='РЕЙД-КОНСТРУКТОР'!K23 -> 0 | D32: =IF(OR($B$5="",$B$6=""),"—",IF(IFERROR(INDEX(ТЕХ_Списки!$V$2:$V$71,MATCH($B$5&"§"&$B$6,ТЕХ_Списки!$D$2:$D$71,0)),0)=1,"✓","—")) -> — | E32: =IF(OR($F$5="",$F$6=""),"—",IF(IFERROR(INDEX(ТЕХ_Списки!$V$2:$V$71,MATCH($F$5&"§"&$F$6,ТЕХ_Списки!$D$2:$D$71,0)),0)=1,"✓","—")) -> — | F32: =IF(D32=E32,"Одинаково",IF(D32="✓","Только A","Только B")) -> Одинаково | G32: ='РЕЙД-КОНСТРУКТОР'!M23 -> Опционально | H32: ='РЕЙД-КОНСТРУКТОР'!N23 -> 1
A33: Утилити-бафы | B33: Fire Resistance | C33: ='РЕЙД-КОНСТРУКТОР'!K24 -> 0 | D33: =IF(OR($B$5="",$B$6=""),"—",IF(IFERROR(INDEX(ТЕХ_Списки!$W$2:$W$71,MATCH($B$5&"§"&$B$6,ТЕХ_Списки!$D$2:$D$71,0)),0)=1,"✓","—")) -> ✓ | E33: =IF(OR($F$5="",$F$6=""),"—",IF(IFERROR(INDEX(ТЕХ_Списки!$W$2:$W$71,MATCH($F$5&"§"&$F$6,ТЕХ_Списки!$D$2:$D$71,0)),0)=1,"✓","—")) -> — | F33: =IF(D33=E33,"Одинаково",IF(D33="✓","Только A","Только B")) -> Только A | G33: ='РЕЙД-КОНСТРУКТОР'!M24 -> Опционально | H33: ='РЕЙД-КОНСТРУКТОР'!N24 -> 1
A34: Утилити-бафы | B34: Frost Resistance | C34: ='РЕЙД-КОНСТРУКТОР'!K25 -> 0 | D34: =IF(OR($B$5="",$B$6=""),"—",IF(IFERROR(INDEX(ТЕХ_Списки!$X$2:$X$71,MATCH($B$5&"§"&$B$6,ТЕХ_Списки!$D$2:$D$71,0)),0)=1,"✓","—")) -> — | E34: =IF(OR($F$5="",$F$6=""),"—",IF(IFERROR(INDEX(ТЕХ_Списки!$X$2:$X$71,MATCH($F$5&"§"&$F$6,ТЕХ_Списки!$D$2:$D$71,0)),0)=1,"✓","—")) -> — | F34: =IF(D34=E34,"Одинаково",IF(D34="✓","Только A","Только B")) -> Одинаково | G34: ='РЕЙД-КОНСТРУКТОР'!M25 -> Опционально | H34: ='РЕЙД-КОНСТРУКТОР'!N25 -> 1
A35: Утилити-бафы | B35: Nature Resistance | C35: ='РЕЙД-КОНСТРУКТОР'!K26 -> 0 | D35: =IF(OR($B$5="",$B$6=""),"—",IF(IFERROR(INDEX(ТЕХ_Списки!$Y$2:$Y$71,MATCH($B$5&"§"&$B$6,ТЕХ_Списки!$D$2:$D$71,0)),0)=1,"✓","—")) -> — | E35: =IF(OR($F$5="",$F$6=""),"—",IF(IFERROR(INDEX(ТЕХ_Списки!$Y$2:$Y$71,MATCH($F$5&"§"&$F$6,ТЕХ_Списки!$D$2:$D$71,0)),0)=1,"✓","—")) -> ✓ | F35: =IF(D35=E35,"Одинаково",IF(D35="✓","Только A","Только B")) -> Только B | G35: ='РЕЙД-КОНСТРУКТОР'!M26 -> Опционально | H35: ='РЕЙД-КОНСТРУКТОР'!N26 -> 1
A36: Утилити-бафы | B36: Shadow Resistance | C36: ='РЕЙД-КОНСТРУКТОР'!K27 -> 0 | D36: =IF(OR($B$5="",$B$6=""),"—",IF(IFERROR(INDEX(ТЕХ_Списки!$Z$2:$Z$71,MATCH($B$5&"§"&$B$6,ТЕХ_Списки!$D$2:$D$71,0)),0)=1,"✓","—")) -> ✓ | E36: =IF(OR($F$5="",$F$6=""),"—",IF(IFERROR(INDEX(ТЕХ_Списки!$Z$2:$Z$71,MATCH($F$5&"§"&$F$6,ТЕХ_Списки!$D$2:$D$71,0)),0)=1,"✓","—")) -> — | F36: =IF(D36=E36,"Одинаково",IF(D36="✓","Только A","Только B")) -> Только A | G36: ='РЕЙД-КОНСТРУКТОР'!M27 -> Опционально | H36: ='РЕЙД-КОНСТРУКТОР'!N27 -> 1
A37: Утилити-бафы | B37: Arcane Resistance | C37: ='РЕЙД-КОНСТРУКТОР'!K28 -> 0 | D37: =IF(OR($B$5="",$B$6=""),"—",IF(IFERROR(INDEX(ТЕХ_Списки!$AA$2:$AA$71,MATCH($B$5&"§"&$B$6,ТЕХ_Списки!$D$2:$D$71,0)),0)=1,"✓","—")) -> — | E37: =IF(OR($F$5="",$F$6=""),"—",IF(IFERROR(INDEX(ТЕХ_Списки!$AA$2:$AA$71,MATCH($F$5&"§"&$F$6,ТЕХ_Списки!$D$2:$D$71,0)),0)=1,"✓","—")) -> — | F37: =IF(D37=E37,"Одинаково",IF(D37="✓","Только A","Только B")) -> Одинаково | G37: ='РЕЙД-КОНСТРУКТОР'!M28 -> Опционально | H37: ='РЕЙД-КОНСТРУКТОР'!N28 -> 1
A38: Утилити-бафы | B38: 5% Resource Reduction | C38: ='РЕЙД-КОНСТРУКТОР'!K29 -> 0 | D38: =IF(OR($B$5="",$B$6=""),"—",IF(IFERROR(INDEX(ТЕХ_Списки!$AB$2:$AB$71,MATCH($B$5&"§"&$B$6,ТЕХ_Списки!$D$2:$D$71,0)),0)=1,"✓","—")) -> — | E38: =IF(OR($F$5="",$F$6=""),"—",IF(IFERROR(INDEX(ТЕХ_Списки!$AB$2:$AB$71,MATCH($F$5&"§"&$F$6,ТЕХ_Списки!$D$2:$D$71,0)),0)=1,"✓","—")) -> — | F38: =IF(D38=E38,"Одинаково",IF(D38="✓","Только A","Только B")) -> Одинаково | G38: ='РЕЙД-КОНСТРУКТОР'!M29 -> Опционально | H38: ='РЕЙД-КОНСТРУКТОР'!N29 -> 1
A39: Утилити-бафы | B39: 3% Damage Reduction (all) | C39: ='РЕЙД-КОНСТРУКТОР'!K30 -> 0 | D39: =IF(OR($B$5="",$B$6=""),"—",IF(IFERROR(INDEX(ТЕХ_Списки!$AC$2:$AC$71,MATCH($B$5&"§"&$B$6,ТЕХ_Списки!$D$2:$D$71,0)),0)=1,"✓","—")) -> — | E39: =IF(OR($F$5="",$F$6=""),"—",IF(IFERROR(INDEX(ТЕХ_Списки!$AC$2:$AC$71,MATCH($F$5&"§"&$F$6,ТЕХ_Списки!$D$2:$D$71,0)),0)=1,"✓","—")) -> — | F39: =IF(D39=E39,"Одинаково",IF(D39="✓","Только A","Только B")) -> Одинаково | G39: ='РЕЙД-КОНСТРУКТОР'!M30 -> Критично | H39: ='РЕЙД-КОНСТРУКТОР'!N30 -> 3
A40: Утилити-бафы | B40: 6% Healing Done | C40: ='РЕЙД-КОНСТРУКТОР'!K31 -> 0 | D40: =IF(OR($B$5="",$B$6=""),"—",IF(IFERROR(INDEX(ТЕХ_Списки!$AD$2:$AD$71,MATCH($B$5&"§"&$B$6,ТЕХ_Списки!$D$2:$D$71,0)),0)=1,"✓","—")) -> — | E40: =IF(OR($F$5="",$F$6=""),"—",IF(IFERROR(INDEX(ТЕХ_Списки!$AD$2:$AD$71,MATCH($F$5&"§"&$F$6,ТЕХ_Списки!$D$2:$D$71,0)),0)=1,"✓","—")) -> — | F40: =IF(D40=E40,"Одинаково",IF(D40="✓","Только A","Только B")) -> Одинаково | G40: ='РЕЙД-КОНСТРУКТОР'!M31 -> Опционально | H40: ='РЕЙД-КОНСТРУКТОР'!N31 -> 1
A41: Утилити-бафы | B41: Concentration | C41: ='РЕЙД-КОНСТРУКТОР'!K32 -> 0 | D41: =IF(OR($B$5="",$B$6=""),"—",IF(IFERROR(INDEX(ТЕХ_Списки!$AE$2:$AE$71,MATCH($B$5&"§"&$B$6,ТЕХ_Списки!$D$2:$D$71,0)),0)=1,"✓","—")) -> — | E41: =IF(OR($F$5="",$F$6=""),"—",IF(IFERROR(INDEX(ТЕХ_Списки!$AE$2:$AE$71,MATCH($F$5&"§"&$F$6,ТЕХ_Списки!$D$2:$D$71,0)),0)=1,"✓","—")) -> — | F41: =IF(D41=E41,"Одинаково",IF(D41="✓","Только A","Только B")) -> Одинаково | G41: ='РЕЙД-КОНСТРУКТОР'!M32 -> Опционально | H41: ='РЕЙД-КОНСТРУКТОР'!N32 -> 1
A42: Утилити-бафы | B42: Amplify Magic | C42: ='РЕЙД-КОНСТРУКТОР'!K33 -> 0 | D42: =IF(OR($B$5="",$B$6=""),"—",IF(IFERROR(INDEX(ТЕХ_Списки!$AF$2:$AF$71,MATCH($B$5&"§"&$B$6,ТЕХ_Списки!$D$2:$D$71,0)),0)=1,"✓","—")) -> — | E42: =IF(OR($F$5="",$F$6=""),"—",IF(IFERROR(INDEX(ТЕХ_Списки!$AF$2:$AF$71,MATCH($F$5&"§"&$F$6,ТЕХ_Списки!$D$2:$D$71,0)),0)=1,"✓","—")) -> — | F42: =IF(D42=E42,"Одинаково",IF(D42="✓","Только A","Только B")) -> Одинаково | G42: ='РЕЙД-КОНСТРУКТОР'!M33 -> Опционально | H42: ='РЕЙД-КОНСТРУКТОР'!N33 -> 1
A43: Утилити-бафы | B43: Dampen Magic | C43: ='РЕЙД-КОНСТРУКТОР'!K34 -> 0 | D43: =IF(OR($B$5="",$B$6=""),"—",IF(IFERROR(INDEX(ТЕХ_Списки!$AG$2:$AG$71,MATCH($B$5&"§"&$B$6,ТЕХ_Списки!$D$2:$D$71,0)),0)=1,"✓","—")) -> — | E43: =IF(OR($F$5="",$F$6=""),"—",IF(IFERROR(INDEX(ТЕХ_Списки!$AG$2:$AG$71,MATCH($F$5&"§"&$F$6,ТЕХ_Списки!$D$2:$D$71,0)),0)=1,"✓","—")) -> — | F43: =IF(D43=E43,"Одинаково",IF(D43="✓","Только A","Только B")) -> Одинаково | G43: ='РЕЙД-КОНСТРУКТОР'!M34 -> Опционально | H43: ='РЕЙД-КОНСТРУКТОР'!N34 -> 1
...

Sheet КАТАЛОГ СПЕКОВ
A1: КАТАЛОГ СПЕЦИАЛИЗАЦИЙ — ФИЛЬТРЫ И ПОЛЬЗА ДЛЯ ТЕКУЩЕГО РЕЙДА
A2: Фильтруй по классу и роли. Колонки «Новых эффектов», «Балл» и «Что закроет» пересчитываются относительно состава на листе «РЕЙД-КОНСТРУКТОР».
A3: Класс | B3: Специализация | C3: Роль | D3: Всего эффектов | E3: Физические бафы | F3: Кастерские бафы | G3: Утилити-бафы | H3: Физические дебафы | I3: Магические дебафы | J3: Утилити-дебафы | K3: Итоговые бафы | L3: Итоговые дебафы | M3: Новых эффектов | N3: Балл | O3: Что закроет | P3: Источник
A4: Barbarian | B4: Ancestry | C4: Саппорт | D4: 7 | E4: 3 | F4: 0 | G4: 3 | H4: 0 | I4: 1 | J4: 0 | K4: Strength; Agility; Attack Power; Concentration; Armor; Heroism | Bloodlust | L4: Resistance Reduction | M4: =ТЕХ_Расчет!F50 -> 7 | N4: =ТЕХ_Расчет!G50 -> 16 | O4: =ТЕХ_Расчет!K50 -> #NAME? | P4: https://coa-raid-comp.ascension.gg/
A5: Barbarian | B5: Brutality | C5: Мили-DPS | D5: 8 | E5: 4 | F5: 0 | G5: 1 | H5: 3 | I5: 0 | J5: 0 | K5: Strength; Agility; Attack Power; Concentration; 5% Attack Power | L5: 4% Physical Damage; 30% Bleed Damage; Armor Reduction | M5: =ТЕХ_Расчет!F51 -> 8 | N5: =ТЕХ_Расчет!G51 -> 17 | O5: =ТЕХ_Расчет!K51 -> #NAME? | P5: https://coa-raid-comp.ascension.gg/
A6: Barbarian | B6: Headhunting | C6: Рейндж/кастер | D6: 8 | E6: 4 | F6: 0 | G6: 2 | H6: 1 | I6: 0 | J6: 1 | K6: Strength; Agility; Attack Power; Concentration; 3% Critical Strike (all); 5% Attack Power | L6: 30% Bleed Damage; Healing Reduction | M6: =ТЕХ_Расчет!F52 -> 8 | N6: =ТЕХ_Расчет!G52 -> 15 | O6: =ТЕХ_Расчет!K52 -> #NAME? | P6: https://coa-raid-comp.ascension.gg/
A7: Witch Doctor | B7: Shadowhunting | C7: Рейндж/кастер | D7: 10 | E7: 2 | F7: 4 | G7: 2 | H7: 0 | I7: 1 | J7: 1 | K7: Small Resistances (all); Intellect; Spirit; Mana Regeneration; 5% Resource Reduction; 10% Melee & Range Haste; 3% Spell Haste; 5% Attack Power | L7: Cast Speed Slow; Resistance Reduction | M7: =ТЕХ_Расчет!F53 -> 10 | N7: =ТЕХ_Расчет!G53 -> 21 | O7: =ТЕХ_Расчет!K53 -> #NAME? | P7: https://coa-raid-comp.ascension.gg/
A8: Witch Doctor | B8: Voodoo | C8: Рейндж/кастер | D8: 10 | E8: 0 | F8: 4 | G8: 3 | H8: 0 | I8: 1 | J8: 2 | K8: Small Resistances (all); Intellect; Spirit; Mana Regeneration; 5% Resource Reduction; 3% Spell Haste; 3% Damage Done (all) | L8: Cast Speed Slow; Attack Speed Slow; Resistance Reduction | M8: =ТЕХ_Расчет!F54 -> 10 | N8: =ТЕХ_Расчет!G54 -> 21 | O8: =ТЕХ_Расчет!K54 -> #NAME? | P8: https://coa-raid-comp.ascension.gg/
A9: Witch Doctor | B9: Brewing | C9: Хилер | D9: 10 | E9: 0 | F9: 5 | G9: 2 | H9: 0 | I9: 1 | J9: 2 | K9: Small Resistances (all); Intellect; Spirit; Mana Regeneration; 5% Resource Reduction; 3% Spell Haste; Replenishment | L9: Cast Speed Slow; Attack Power Reduction; Resistance Reduction | M9: =ТЕХ_Расчет!F55 -> 10 | N9: =ТЕХ_Расчет!G55 -> 21 | O9: =ТЕХ_Расчет!K55 -> #NAME? | P9: https://coa-raid-comp.ascension.gg/
A10: Felsworn | B10: Infernal | C10: Рейндж/кастер | D10: 8 | E10: 2 | F10: 0 | G10: 3 | H10: 0 | I10: 2 | J10: 1 | K10: Minor Armor and All Stats; Attack Power; Fire Resistance; Shadow Resistance; 3% Critical Strike (all) | L10: Damage Done Reduction (5%); 3% Spell Hit; 10% Spell Damage | M10: =ТЕХ_Расчет!F56 -> 8 | N10: =ТЕХ_Расчет!G56 -> 18 | O10: =ТЕХ_Расчет!K56 -> #NAME? | P10: https://coa-raid-comp.ascension.gg/
A11: Felsworn | B11: Tyrant | C11: Танк | D11: 11 | E11: 3 | F11: 0 | G11: 4 | H11: 1 | I11: 0 | J11: 3 | K11: Minor Armor and All Stats; Attack Power; Fire Resistance; Shadow Resistance; 10% Melee & Range Haste; 3% Damage Done (all); Defensive Cooldown (Raid-Wide) | L11: 4% Physical Damage; Attack Power Reduction; Attack Speed Slow; Damage Done Reduction (5%) | M11: =ТЕХ_Расчет!F57 -> 11 | N11: =ТЕХ_Расчет!G57 -> 27 | O11: =ТЕХ_Расчет!K57 -> #NAME? | P11: https://coa-raid-comp.ascension.gg/
A12: Felsworn | B12: Slaying | C12: Мили-DPS | D12: 10 | E12: 3 | F12: 0 | G12: 3 | H12: 1 | I12: 0 | J12: 3 | K12: Minor Armor and All Stats; Attack Power; Fire Resistance; Shadow Resistance; 10% Melee & Range Haste; Armor | L12: Healing Reduction; Cast Speed Slow; Armor Reduction; Damage Done Reduction (5%) | M12: =ТЕХ_Расчет!F58 -> 10 | N12: =ТЕХ_Расчет!G58 -> 20 | O12: =ТЕХ_Расчет!K58 -> #NAME? | P12: https://coa-raid-comp.ascension.gg/
A13: Witch Hunter | B13: Inquisition | C13: Мили-DPS | D13: 7 | E13: 3 | F13: 1 | G13: 1 | H13: 0 | I13: 0 | J13: 2 | K13: Minor Armor and All Stats; Attack Power; Mana Regeneration; Shadow Resistance; 10% Melee & Range Haste | L13: Cast Speed Slow; Damage Done Reduction (5%) | M13: =ТЕХ_Расчет!F59 -> 7 | N13: =ТЕХ_Расчет!G59 -> 14 | O13: =ТЕХ_Расчет!K59 -> #NAME? | P13: https://coa-raid-comp.ascension.gg/
A14: Witch Hunter | B14: Houndmaster | C14: Рейндж/кастер | D14: 7 | E14: 3 | F14: 2 | G14: 1 | H14: 0 | I14: 0 | J14: 1 | K14: Minor Armor and All Stats; Attack Power; Mana Regeneration; Shadow Resistance; 3% Spell Haste; 5% Attack Power | L14: Cast Speed Slow | M14: =ТЕХ_Расчет!F60 -> 7 | N14: =ТЕХ_Расчет!G60 -> 14 | O14: =ТЕХ_Расчет!K60 -> #NAME? | P14: https://coa-raid-comp.ascension.gg/
A15: Witch Hunter | B15: Black Knight | C15: Танк | D15: 8 | E15: 2 | F15: 2 | G15: 2 | H15: 0 | I15: 0 | J15: 2 | K15: Minor Armor and All Stats; Attack Power; Mana Regeneration; Shadow Resistance; Replenishment; Defensive Cooldown (Raid-Wide) | L15: Cast Speed Slow; Attack Speed Slow | M15: =ТЕХ_Расчет!F61 -> 8 | N15: =ТЕХ_Расчет!G61 -> 17 | O15: =ТЕХ_Расчет!K61 -> #NAME? | P15: https://coa-raid-comp.ascension.gg/
... A73: Tinker | B73: Invention | C73: Хилер | D73: 8 | E73: 1 | F73: 3 | G73: 4 | H73: 0 | I73: 0 | J73: 0 | K73: Attack Power; Mana Regeneration; Strong Mana Cooldown; Concentration; Amplify Magic; 3% Spell Haste; 3% Damage Reduction (all); 6% Healing Done | L73: — | M73: =ТЕХ_Расчет!F119 -> 8 | N73: =ТЕХ_Расчет!G119 -> 14 | O73: =ТЕХ_Расчет!K119 -> #NAME? | P73: https://coa-raid-comp.ascension.gg/

Sheet СПРАВОЧНИК ЭФФЕКТОВ
A1: СПРАВОЧНИК ЭФФЕКТОВ И ТЕКУЩЕЕ ПОКРЫТИЕ
A2: Покрытие рассчитывается по текущему составу на первой странице. Приоритет меняется в жёлтом столбце C. Здесь же находятся полный список источников и редкость каждого эффекта.
A3: Категория | B3: Эффект | C3: Приоритет | D3: В рейде | E3: Статус | F3: Спеков-источников | G3: Классов-источников | H3: Роли | I3: Все источники | J3: Ключ базы | K3: Источник | L3: Коротко: кто закрывает | M3: Вес
A4: Физические бафы | B4: 10% Stats | C4: Критично | D4: ='РЕЙД-КОНСТРУКТОР'!K6 -> 0 | E4: =IF(D4=0,"НЕ ХВАТАЕТ",IF(D4=1,"ЕСТЬ","ЕСТЬ ЗАПАС")) -> НЕ ХВАТАЕТ | F4: 14 | G4: 4 | H4: Мили-DPS, Рейндж/кастер, Танк, Хилер | I4: Cultist — Heretic; Cultist — Dreadnought; Cultist — Corruption; Cultist — Godblade; Sun Cleric — Blessings; Sun Cleric — Valkyrie; Sun Cleric — Piety; Sun Cleric — Seraphim; Templar — Zealot; Templar — Crusader; Templar — Oathkeeper; Runemaster — Glyphic; Runemaster — Riftblade; Runemaster — Engravement | J4: Stats % (Kings) | K4: https://coa-raid-comp.ascension.gg/ | L4: Cultist — любой спек; Runemaster — любой спек; Sun Cleric — любой спек; Templar — любой спек | M4: =IF(C4="Критично",3,IF(C4="Важно",2,IF(C4="Опционально",1,0))) -> 3
A5: Физические бафы | B5: Minor Armor and All Stats | C5: Важно | D5: ='РЕЙД-КОНСТРУКТОР'!K7 -> 0 | E5: =IF(D5=0,"НЕ ХВАТАЕТ",IF(D5=1,"ЕСТЬ","ЕСТЬ ЗАПАС")) -> НЕ ХВАТАЕТ | F5: 18 | G5: 5 | H5: Мили-DPS, Рейндж/кастер, Саппорт, Танк, Хилер | I5: Felsworn — Infernal; Felsworn — Tyrant; Felsworn — Slaying; Witch Hunter — Inquisition; Witch Hunter — Houndmaster; Witch Hunter — Black Knight; Witch Hunter — Boltslinger; Primalist — Wildwalker; Primalist — Mountain King; Primalist — Geomancy; Primalist — Grovekeeper; Ranger — Brigand; Ranger — Archery; Ranger — Farstrider; Venomancer — Stalking; Venomancer — Vizier; Venomancer — Fortitude; Venomancer — Rot | J5: Stats Flat + Armor (MotW) | K5: https://coa-raid-comp.ascension.gg/ | L5: Felsworn — любой спек; Primalist — любой спек; Ranger — любой спек; Venomancer — любой спек; + ещё 1 классов | M5: =IF(C5="Критично",3,IF(C5="Важно",2,IF(C5="Опционально",1,0))) -> 2
A6: Физические бафы | B6: Stamina | C6: Важно | D6: ='РЕЙД-КОНСТРУКТОР'!K8 -> 0 | E6: =IF(D6=0,"НЕ ХВАТАЕТ",IF(D6=1,"ЕСТЬ","ЕСТЬ ЗАПАС")) -> НЕ ХВАТАЕТ | F6: 13 | G6: 4 | H6: Мили-DPS, Рейндж/кастер, Саппорт, Танк | I6: Knight of Xoroth — Hellfire; Knight of Xoroth — War; Knight of Xoroth — Defiance; Bloodmage — Sanguine; Bloodmage — Fleshweaver; Bloodmage — Accursed; Bloodmage — Eternal; Reaper — Soul; Reaper — Harvest; Reaper — Domination; Necromancer — Animation; Necromancer — Death; Necromancer — Rime | J6: Stamina (Fort) | K6: https://coa-raid-comp.ascension.gg/ | L6: Bloodmage — любой спек; Knight of Xoroth — любой спек; Necromancer — любой спек; Reaper — любой спек | M6: =IF(C6="Критично",3,IF(C6="Важно",2,IF(C6="Опционально",1,0))) -> 2
A7: Физические бафы | B7: Strength | C7: Важно | D7: ='РЕЙД-КОНСТРУКТОР'!K9 -> 0 | E7: =IF(D7=0,"НЕ ХВАТАЕТ",IF(D7=1,"ЕСТЬ","ЕСТЬ ЗАПАС")) -> НЕ ХВАТАЕТ | F7: 12 | G7: 4 | H7: Мили-DPS, Рейндж/кастер, Саппорт, Танк | I7: Barbarian — Ancestry; Barbarian — Brutality; Barbarian — Headhunting; Knight of Xoroth — Hellfire; Knight of Xoroth — War; Knight of Xoroth — Defiance; Guardian — Vanguard; Guardian — Gladiator; Guardian — Inspiration; Reaper — Soul; Reaper — Harvest; Reaper — Domination | J7: Flat Strength | K7: https://coa-raid-comp.ascension.gg/ | L7: Barbarian — любой спек; Guardian — любой спек; Knight of Xoroth — любой спек; Reaper — любой спек | M7: =IF(C7="Критично",3,IF(C7="Важно",2,IF(C7="Опционально",1,0))) -> 2
